Workbook

Sheet Campaigns
A1: Campaign ID | B1: Campaign Name | C1: Date of Campaign Launch | D1: Strategic Framework (Full GET/TO/BY) | E1: Hypothesis (IF/THEN) | F1: Learning | G1: Highlights | H1: Lowlights | I1: Next Steps & Implications | J1: Product | K1: Channels Included | L1: Campaign Success Status | M1: Business Impact | N1: Wrap Report Link | O1: Primary Experiment Metric 1 | P1: ITC - 1 | Q1: Primary Experiment Metric 2 | R1: ITC - 2 | S1: Primary Experiment Metric 3 | T1: ITC - 3 | U1: Table Data | V1: Misc | W1: Slide Number(s) | X1: Slide Deck Name | Y1: Source Match | Z1: Strategic Framework - GET | AA1: Strategic Framework - TO | AB1: Strategic Framework - BY
A2: ELM-3877 | B2: Q3 Data in Context Campaign: Inflation | D2: GET: QBO Subscribers TO: acknowledge QBO as a key partner in running their business BY: letting they know how they stand across the QB community in the context of the economic challenges. | E2: IF: If we leverage customer's aggregate data to highlight QuickBooks as a solution to an issue facing SMBs THEN: We will see an increase in retention. | F2: • Customers that were eligible for the Data in Context since FY'22 Q3 (ELM-3877) were kept on the same treatment and control groups to see the cumulative impact of these campaigns . • There is not a significant difference in long-term retention between the customers that receive the series of 4 DiC campaigns and those that did not. | J2: QBO | L2: Positive | M2: We have not detected a stat sig impact improvement in 01-year retention. | U2: [["KPIs", "TEST", "CON.", "Δ (%pts)", "ITC"], ["Sample Size", "1,532,350", "269,630", "", ""], ["04m Churn", "6.39%", "6.40%", "-0.01%", "99.84"], ["06m Churn", "8.54%", "8.62%", "-0.08%", "99.07"], ["09m Churn", "11.31%", "11.37%", "-0.06%", "99.47"], ["01y Churn", "14.38%", "14.49%", "-0.11", "99.24"]] | V2: ⚠️ Not found in ELM Roadmap or Results Report | W2: 96 | X2: Copy of Copy of CRM Analytics 2023 AC.pptx | Y2: ⚠️ ELM Roadmap | ⚠️ Results Report | Z2: QBO Subscribers | AA2: acknowledge QBO as a key partner in running their business | AB2: letting they know how they stand across the QB community in the context of the economic challenges.
A3: ELM-3922 | B3: Personalize QBO FTU with GTKM - UBF | C3: 01-05-2023 | D3: GET: QuickBooks Online NTTF customers TO: deliver 2,208 units in FY'24 & ~$1.2M in annual revenue from those units. BY: the campaign at 100.3 ITC | E3: IF: If we personalize the QBO FTU based on their intent to use QBO THEN: We will increase 31D and 92D retention, and increase the amount of customers that reach QBO POP | F3: • 92d retention for Buy Now was positively impacted by the campaign at 100.3 ITC The experiment showed a flat impact on 92d retention for CCR . 45d conversion was positively impacted by the campaign at 104.4 ITC. • Both emails (new ELM-3922 and current ELM-2933) have a similar reach at ~80% Open Rate is higher in the treatment group (102 ITC) as well as CTR (106 ITC). • The unsub rate have increased (115 ITC), which 280 more customers per month that unsubscribe. • Buy Now and CCR customers in the TREATMENT group have received 2 more emails compared to the CONTROL group (9 vs. 7 emails) The number of emails received by non-CCR customers has stayed the same (9 emails) ELM-3922 have helped increase overall IPD reach from ~58% to ~68% (~10% of new Customers have only seen ELM-3922) and increased overall IPD CTR from ~18% to ~22% Buy Now and non-CCR customers have shown an increase in product feature adoption metrics. CCR Trialers have lower engagement with the QBO features compared to Buy Now and non-CCR customers. | G3: Retesting of flat experiment with improved targeting and placements resulted in higher UBF PoP rates. Early reads to inform iterations resulted in higher engagement and UBF PoP rates. • NEXT STEPS & IMPLICATIONS | H3: Batch attributes allowing us to reach only 60% of the audience. Better coordination between functions ( CS, PM, Marketing) | J3: QBO | K3: IPD; Email | L3: Not found (Inferred for review) | M3: The campaign delivered ~230 incremental units by significantly improving 3-month retention for Buy Now retention (+0.2% & 170 units) and Trial Conversion (+1.3% & 59 units) for the duration of the campaign. Roll-out is estimated to deliver 2,208 units in FY'24 & ~$1.2M in annual revenue from those units. | U3: [["KPIs", "TEST", "CON.", "ITC"], ["Sample Size", "79,488", "79,133", ""], ["92d Retention (BN)", "83.4%", "83.2%", "100.3"], ["92d Retention (Trial CCR)", "31.6%", "32.3%", "97.8"], ["45d Conversion (Trial non-CCR)", "30.9%", "29.6%", "104.4"], ["Cohort", "Email", "", "", "", "", "", "", "", "", "", "", "", "", "IPD", "", ""], ["", "Sent", "Opens", "%", "Δ", "ITC", "Clicks", "CTR", "Δ", "ITC", "Unsub", "%", "Δ", "ITC", "Imp.", "Clicks", "CTR"], ["CONTROL", "105,773", "68,629", "64.9%", "", "", "17,203", "16.3%", "", "", "2,786", "2.6%", "", "", "", "", ""], ["TREATMENT", "106,183", "70,534", "66.4%", "1.5%", "102", "18,410", "17.3%", "1%", "106", "3,182", "3.0%", "0.4%", "115", "45,718", "6,087", "13.3%"], ["ELM Channel Reach", "", "", "", ""], ["KPIs", "TEST", "CON.", "Δ", "ITC"], ["Sample Size", "75,928", "75,617", "", ""], ["QBO FTU Email Reach", "81.3%", "81.0%", "0.3%", "100.4"], ["QBO FTU IPD Reach", "68.4%", "57.9%", "10.5%", "118.2"], ["QBO FTU IPD CTR", "21.8%", "18.3%", "3.6%", "119.5"], ["Signup Type", "Size", "", "31d Bank Connected", "", "", "31d Txn Added\n(At least 1 txn added while having connected a bank)", "", "", "31d UBF POP", "", "", "92d Retention (BN & CCR)\n45d Conversion (non-CCR)", "", ""], ["", "TREATMENT", "CONTROL", "TREATMENT", "CONTROL", "ITC", "TREATMENT", "CONTROL", "ITC", "TREATMENT", "CONTROL", "ITC", "TREATMENT", "CONTROL", "ITC"], ["Buy Now", "69,671", "69,502", "70.3%", "70.1%", "100.3", "69.2%", "69.1%", "100.2", "15.2%", "15.1%", "100.7", "83.4%", "83.2%", "100.3"], ["CCR", "5,288", "5,133", "44.6%", "45.1%", "99.0", "43.6%", "43.9%", "99.3", "7.3%", "7.7%", "94.1", "31.6%", "32.3%", "97.8"], ["non-CCR", "4,528", "4,495", "49.8%", "47.7%", "104.3", "48.7%", "46.7%", "104.1", "9.8%", "9.9%", "99.3", "30.9%", "29.6%", "104.4"], ["KPIs", "TEST", "CON.", "ITC"], ["Sample Size", "79,488", "79,133", ""], ["92d Retention (BN)", "83.4%", "83.2%", "100.3"], ["92d Retention (Trial CCR)", "31.6%", "32.3%", "97.8"], ["45d Conversion (Trial non-CCR)", "30.9%", "29.6%", "104.4"], ["Cohort", "Email", "", "", "", "", "", "", "", "", "", "", "", "", "IPD", "", ""], ["", "Sent", "Opens", "%", "Δ", "ITC", "Clicks", "CTR", "Δ", "ITC", "Unsub", "%", "Δ", "ITC", "Imp.", "Clicks", "CTR"], ["CONTROL", "105,773", "68,629", "64.9%", "", "", "17,203", "16.3%", "", "", "2,786", "2.6%", "", "", "", "", ""], ["TREATMENT", "106,183", "70,534", "66.4%", "1.5%", "102", "18,410", "17.3%", "1%", "106", "3,182", "3.0%", "0.4%", "115", "45,718", "6,087", "13.3%"], ["ELM Channel Reach", "", "", "", ""], ["KPIs", "TEST", "CON.", "Δ", "ITC"], ["Sample Size", "75,928", "75,617", "", ""], ["QBO FTU Email Reach", "81.3%", "81.0%", "0.3%", "100.4"], ["QBO FTU IPD Reach", "68.4%", "57.9%", "10.5%", "118.2"], ["QBO FTU IPD CTR", "21.8%", "18.3%", "3.6%", "119.5"], ["Signup Type", "Size", "", "31d Bank Connected", "", "", "31d Txn Added\n(At least 1 txn added while having connected a bank)", "", "", "31d UBF POP", "", "", "92d Retention (BN & CCR)\n45d Conversion (non-CCR)", "", ""], ["", "TREATMENT", "CONTROL", "TREATMENT", "CONTROL", "ITC", "TREATMENT", "CONTROL", "ITC", "TREATMENT", "CONTROL", "ITC", "TREATMENT", "CONTROL", "ITC"], ["Buy Now", "69,671", "69,502", "70.3%", "70.1%", "100.3", "69.2%", "69.1%", "100.2", "15.2%", "15.1%", "100.7", "83.4%", "83.2%", "100.3"], ["CCR", "5,288", "5,133", "44.6%", "45.1%", "99.0", "43.6%", "43.9%", "99.3", "7.3%", "7.7%", "94.1", "31.6%", "32.3%", "97.8"], ["non-CCR", "4,528", "4,495", "49.8%", "47.7%", "104.3", "48.7%", "46.7%", "104.1", "9.8%", "9.9%", "99.3", "30.9%", "29.6%", "104.4"], ["HIGHLIGHTS", "", "LOWLIGHTS"], ["Retesting of flat experiment with improved targeting and placements resulted in higher UBF PoP rates.\nEarly reads to inform iterations resulted in higher engagement and UBF PoP rates.", "", "Batch attributes allowing us to reach only 60% of the audience.\nBetter coordination between functions ( CS, PM, Marketing)"], ["NEXT STEPS & IMPLICATIONS", "", ""]] | V3: Alt Name (slide 14): ● | Alt Date (slide 14): 08/10/2023 | Alt Product (slide 14): QuickBooks Online | Alt Name (slide 15): and current ELM-2933) have a similar reach at ~80% | Alt TO (slide 15): mers per month that unsubscribe. | Alt BY (slide 15): non-CCR customers has stayed the same (9 emails) | Alt TO (slide 16): mers have shown an increase in product feature adoption metrics. | Alt Name (slide 41): ● | Alt Date (slide 41): 08/10/2023 | Alt Product (slide 41): QuickBooks Online | Alt Name (slide 42): and current ELM-2933) have a similar reach at ~80% | Alt TO (slide 42): mers per month that unsubscribe. | Alt BY (slide 42): non-CCR customers has stayed the same (9 emails) | Alt TO (slide 43): mers have shown an increase in product feature adoption metrics. | Alt Product (slide 323): Payments | Alt GET (slide 323): ing and placements resulted in higher UBF PoP rates. | Alt TO (slide 323): inform iterations resulted in higher engagement and UBF PoP rates. | Batch attri | Date: CSV-Current | W3: 13-323 | X3: Copy of Copy of CRM Analytics 2023 AC.pptx | Y3: ✅ ELM Roadmap | ⚠️ Results Report | Z3: QuickBooks Online NTTF customers | AA3: deliver 2,208 units in FY'24 & ~$1.2M in annual revenue from those units. | AB3: the campaign at 100.3 ITC
A4: ELM-3938 | B4: Proactive Intervention | C4: 08-17-2022 | D4: GET: QBO Buy Now and Trialers who have not connected a bank by day 3 or categorized < 60% transactions from day 3 to 31 of sign up TO: the digital assistant, we can enable customers to connect to support. BY: day 3 or categorized < 60% transactions from day 3 to 31 of sign up | E4: IF: If we implement human assisted intervention IPDs for NTTF Trailers + Buy Now customers THEN: We will increase the number of customers who reach the UBF payoff event for QBO. (Inferred for review) | F4: • Overall the self serve content is highly engaging and helpful for users to connect bank and categorize transactions. CTR is quite high because of two CTA's. • Opportunity to improve Human Assisted experience further and add additional placements to improve reach and engagement. • Users who engage with Human Assisted content prefer both options call me back and schedule a call back. 70% of those who engage with Human Assisted offers schedule a call and ~ 96% of those calls are handled by agents. • Overall campaign is performing better for buy now customers as against to the trialers for UBF EPOP. • Buy now customers prefer self serve content more while connecting with the bank but need human assistance while categorizing bank transactions. • Trial customers need human assistance more for both connecting bank and categorizing transactions but QBO POP rate is trending lower compared to the control bucket. • No harm metrics such as 31d retention rate is flat at 100 ITC. | J4: QBO | K4: IPD | L4: Not found (Inferred for review) | M4: This campaign something business impact COHORT | SIZE | % | Bank Connection | Categorize 60% Txn | UBF POP % | Δ | ITC | % | Δ | ITC | % | Δ | ITC Human Assisted | 21.6K | 33% | 23.2% | -0.2 | 99.4 | 18.9% | +0.2 | 101 | 7.7% | +0.1 | 101 Self Serve | 21.7K | 33% | 23.8% | +0.4 | 102 | 19.2% | +0.5 | 103 | 8.1% | +0.5 | 106 Control | 21.8K | 33% | 23.4% | 18.7% | 7.6% This campaign something business impact COHORT | IPD Reach | Unique Clicks | CTR Human Assisted | 14.1K | 325 | 2.3% Self Serve | 14.4K | 1756 | 12.7% | U4: [["HYPO\n-THESIS", "If we implement human assisted intervention IPDs for NTTF Trailers + Buy Now customers, we will increase the number of customers who reach the UBF payoff event for QBO.", "", "", "", ""], ["14d baked data - Early read", "", "", "", "", "", ""], ["KPIs", "", "CONTROL", "HA", "SS", "ITC HA", "ITC SS"], ["UBF POP", "", "7.7%", "7.8%", "8.1%", "101", "106"], ["Retention Rate", "", "94.6%", "94.7%", "94.8%", "100", "100"], ["EPOP", "", "21.9%", "22.3%", "22.7%", "102", "104"], ["BUSINESS IMPACT", "", "", "", "", "", "", "", "", "", "", ""], ["This campaign something something something business impact", "", "", "", "", "", "", "", "", "", "", ""], ["COHORT", "SIZE", "%", "Bank Connection", "", "", "Categorize 60% Txn", "", "", "UBF POP", "", ""], ["", "", "", "%", "Δ", "ITC", "%", "Δ", "ITC", "%", "Δ", "ITC"], ["Human Assisted", "21.6K", "33%", "23.2%", "-0.2", "99.4", "18.9%", "+0.2", "101", "7.7%", "+0.1", "101"], ["Self Serve", "21.7K", "33%", "23.8%", "+0.4", "102", "19.2%", "+0.5", "103", "8.1%", "+0.5", "106"], ["Control", "21.8K", "33%", "23.4%", "", "", "18.7%", "", "", "7.6%", "", ""], ["CHANNEL ENGAGEMENT", "", "", ""], ["This campaign something something something business impact", "", "", ""], ["COHORT", "IPD", "", ""], ["", "Reach", "Unique Clicks", "CTR"], ["Human Assisted", "14.1K", "325", "2.3%"], ["Self Serve", "14.4K", "1756", "12.7%"], ["HYPO\n-THESIS", "If we implement human assisted intervention IPDs for NTTF Trailers + Buy Now customers, we will increase the number of customers who reach the UBF payoff event for QBO.", "", "", "", ""], ["14d baked data - Early read", "", "", "", "", "", ""], ["KPIs", "", "CONTROL", "HA", "SS", "ITC HA", "ITC SS"], ["UBF POP", "", "7.83%", "7.84%", "8.25%", "100", "105"], ["Retention Rate", "", "94.6%", "94.7%", "94.8%", "100", "100"], ["EPOP", "", "22.3%", "22.5%", "22.9%", "101", "103"], ["14d baked data - Early read", "", "", "", "", "", ""], ["Buy Now Customers", "", "", "", "", "", ""], ["KPIs", "", "CONTROL", "HA", "SS", "ITC HA", "ITC SS"], ["Connected Bank", "", "13%", "13.2%", "14%", "101", "107"], ["Categorized 60% Txn", "", "3.95%", "4.14%", "4.06%", "105", "103"], ["UBF EPOP", "", "3.73%", "3.8%", "4.0%", "102", "108"], ["Retention Rate", "", "96.49%", "96.86%", "96.82%", "100", "100"], ["14d baked data - Early read", "", "", "", "", "", ""], ["Trial Customers", "", "", "", "", "", ""], ["KPIs", "", "CONTROL", "HA", "SS", "ITC HA", "ITC SS"], ["Connected Bank", "", "12.6%", "13.7%", "12.1%", "109", "96"], ["Categorized 60% Txn", "", "3.34%", "3.80%", "3.82%", "114", "114"], ["UBF EPOP", "", "2.9%", "2.7%", "2.65%", "93", "92"], ["Retention Rate", "", "98.33%", "98.81%", "97.92%", "100", "100"]] | V4: Alt Date (slide 321): 07-27-2022 | Alt TO (slide 322): connect bank and categorize transactions. CTR is quite high because of two CTA's | Alt BY (slide 322): agents. | Alt Date (slide 338): 07-27-2022 | Date: CSV-Current | W4: 320-340 | X4: Copy of Copy of CRM Analytics 2023 AC.pptx | Y4: ✅ ELM Roadmap | ⚠️ Results Report | Z4: QBO Buy Now and Trialers who have not connected a bank by day 3 or categorized < 60% transactions from day 3 to 31 of sign up | AA4: the digital assistant, we can enable customers to connect to support. | AB4: day 3 or categorized < 60% transactions from day 3 to 31 of sign up
A5: ELM-4240 | B5: Awareness and adoption of new QB Commerce features | C5: 09-29-2022 | D5: GET: QBO customers selling on Amazon, Shopify, or eBay TO: Drive awareness and adoption of new Commerce features (Accounting in Q1 and Inventory/Order Mgmt in Q2). BY: making them feel excited to get more out of QBO by connecting it with their sales channels | E5: IF: we inform and educate e-commerce PBB customers about the Commerce benefits now available within QBO THEN: we will deliver more value to the PBB customer segment, leading to higher segment penetration, customer PRS (product recommendation score) and retention rates. | F5: • The campaign has a positive impact on QB Commerce adoption; however, the adoption rate is still below 1% Despite the increase in adoption, 31d Retention and 92d Retention were flat. 80% of the customers in the treatment group have seen at least 1 of the 8 IPDs we launched. • However, more people have dismissed the IPDs than clicked on them The Banking - Hellobox is the access point with the highest traffic. • It is performance has also been way above average. • Nonetheless, less than 50% of the customers have seen this access point Cohort | IPD Total Assignments | 12,330 | G5: The campaign have successfully increased the % of QBO customers adopting the QB Commerce feature. • NEXT STEPS & IMPLICATIONS • The campaign as it is, should not be made an evergreen campaign since it is not making an impact on retention. Use targeting attributes to make this a dynamic campaign instead of working with list pulls. Explore the use of email channel to explain more what this feature is about | H5: There was no stat sig impact on 31d /92d Retention Even though IPD have shown a stat sig increase in feature adoption, the text limitations could have prevented customers from knowing more about this feature. Working with list pulls limit the ability to increase the number of samples | I5: The campaign as it is, should not be made an evergreen campaign since it is not making an impact on retention. Use targeting attributes to make this a dynamic campaign instead of working with list pulls. Explore the use of email channel to explain more what this feature is about | J5: QBO | K5: IPD | L5: Not found (Inferred for review) | M5: Even though the campaign showed a positive impact on QB Commerce adoption, less than 1% have used this feature, and it had no impact on 31d / 92d Retention. | U5: [["KPIs", "TEST", "CON.", "Δ", "ITC"], ["Sample Size", "12,330", "12,393", "", ""], ["31d Retention", "98.7%", "98.7%", "-0.0%", "99.9"], ["92d Retention", "97.4%", "97.6%", "-0.2%", "99.8"], ["31d Commerce Conn.", "0.9%", "0.6%", "0.3%", "156.4"], ["31d Imported Txn", "0.8%", "0.5%", "0.3%", "163.8"], ["31d Added to Books", "0.2%", "0.2%", "0.1%", "160.0"], ["Cohort", "IPD", "", "", "", "", "", ""], ["", "Imp.", "% of Treatment", "Clicks", "CTR", "Bnchmrk", "Δ", "ITB"], ["Dashboard - Tips", "3,039", "24.6%", "19", "0.6%", "1.0%", "-0.37%", "63"], ["Banking - Hellobox", "5,209", "42.2%", "53", "1.0%", "0.3%", "0.72%", "339"], ["App Center - Hellobox", "552", "4.5%", "14", "2.5%", "N/A", "N/A", "N/A"], ["Income Overview - Tips", "2,155", "17.5%", "4", "0.2%", "0.4%", "-0.21%", "46"], ["Reports - Hellobox", "4,337", "35.2%", "9", "0.2%", "0.1%", "0.11%", "208"], ["Sales - Hellobox", "1,173", "9.5%", "6", "0.5%", "0.1%", "0.41%", "512"], ["Invoices - Hellobox", "4,613", "37.4%", "29", "0.6%", "1.9%", "-1.27%", "33"], ["Chart of Accounts - Hellobox", "3,468", "28.1%", "25", "0.7%", "0.2%", "0.52%", "360"], ["IPD Engagement Funnel", "", ""], ["Total Assignments", "12,330", ""], ["Viewed IPD", "9,854", "79.9%"], ["Clicked IPD", "141", "1.1%"], ["Dismissed IPD", "1,347", "10.9%"], ["HIGHLIGHTS", "", "LOWLIGHTS"], ["The campaign have successfully increased the % of QBO customers adopting the QB Commerce feature.", "", "There was no stat sig impact on 31d /92d Retention\nEven though IPD have shown a stat sig increase in feature adoption, the text limitations could have prevented customers from knowing more about this feature.\nWorking with list pulls limit the ability to increase the number of samples"], ["NEXT STEPS & IMPLICATIONS", "", ""], ["The campaign as it is, should not be made an evergreen campaign since it is not making an impact on retention.\nUse targeting attributes to make this a dynamic campaign instead of working with list pulls.\nExplore the use of email channel to explain more what this feature is about", "", ""]] | V5: Alt Date (slide 284): 09-29-22 | Alt Product (slide 285): Invoicing | Alt TO (slide 285): mers in the treatment group have seen at least 1 of the 8 IPDs we launched. Howe | Alt GET (slide 286): ing attributes to make this a dynamic campaign instead of working with list pull | Alt TO (slide 286): mers adopting the QB Commerce feature. | There was no stat sig impact on 31d /92 | TO replaced with CSV Project Description (was: table_bleed) | Date: CSV-Current | W5: 283-286 | X5: Copy of Copy of CRM Analytics 2023 AC.pptx | Y5: ✅ ELM Roadmap | ⚠️ Results Report | Z5: QBO customers selling on Amazon, Shopify, or eBay | AA5: Drive awareness and adoption of new Commerce features (Accounting in Q1 and Inventory/Order Mgmt in Q2). | AB5: making them feel excited to get more out of QBO by connecting it with their sales channels
A6: ELM-4749 | B6: Promote TangoApp to DTM QBO customers | C6: 10-17-2022 | D6: GET: non Advanced QBO DTM customers TO: non-Advance DTM QBO customers BY: Making them feel confident in their decision to migrate to QBO with an experience that is similar to what they are used to in Desktop. | E6: IF: If we promote the Tango App to DTM QBO customers through IPD, these customers will download the app and use it, which will ultimately make them feel more confident using QBO, resulting in a 1% lift in 31D and 92D retention | F6: • Tango App adoption increased for customers that were part of the DTM experience. • However, that same stat sig increase is not shown in customers that only saw the IPDs. • The impact is only directional Flat 31d Retention (33%) Promote TangoApp to non-Advance customers The IPDs reached ~74% of eligible customers Despite its low coverage, Banking - Hellobox and Customers - Hellobox , the proportion of customers engaging with these access points was much higher | G6: Promoting the Tango App through GTKM, Beanstalk, and the Setup Checklist (DTM experiment) was effective in creating Tango App adoption. • NEXT STEPS & IMPLICATIONS • Track 92d Retention. This metric should be available by March 21st Test if using Email as a channel to promote Tango App has a better impact compared to IPDs Limitation: If the customer opens the email in its mobile, the to download the tango app will not work properly. Dig into why more Importer Migrators were largely targeted by the ELM experience compared to the DTM experience. | H6: The IPDs on their own (ELM experiment) did not show an incremental benefit on Tango App adoption The increase in Tango App adoption did not resulted in an improvement of 31d Retention | I6: Track 92d Retention. This metric should be available by March 21st Test if using Email as a channel to promote Tango App has a better impact compared to IPDs Limitation: If the customer opens the email in its mobile, the to download the tango app will not work properly. Dig into why more Importer Migrators were largely targeted by the ELM experience compared to the DTM experience. | J6: QBO | K6: IPD | L6: Not found (Inferred for review) | M6: The experiments did not show a stat sig impact on 31d Retention. Nonetheless, the IPD + DTM experiment have increased adoption The IPD Only experience did not increased adoption. | U6: [["KPIs", "Control", "IPD Only", "ITC", "DTM + IPD", "ITC"], ["Sample Size", "5,202", "5,174", "", "5,198", ""], ["31d Tango Download", "2.3%", "2.6%", "112.9", "34.0%", "1,448.7"], ["31d Company Selection", "1.1%", "1.4%", "123.1", "22.0%", "1,970.5"], ["31d Opened Tango", "0.8%", "1.0%", "119.2", "17.4%", "2,101.6"], ["31d Retention", "95.3%", "95.3%", "100.0", "95.2%", "99.9"], ["CHANNEL ENGAGEMENT", "", "", "", "", "", ""], ["3 Access Points were used in this campaign", "", "", "", "", "", ""], ["Access Point", "IPD", "", "", "", "", ""], ["", "Imp.", "Clicks", "CTR", "Benchmark", "Δ", "ITB"], ["Chart of Accounts - Hellobox", "5,436", "102", "1.9%", "2.3%", "-0.4%", "83"], ["Banking - Hellobox", "3,254", "84", "2.6%", "1.9%", "0.7%", "136"], ["Customers - Hellobox", "3,035", "64", "2.1%", "1.9%", "0.2%", "113"], ["Funnel", "Customers", "% Customers"], ["Treatment", "10,372", ""], ["Impressions", "7,728", "74.5%"], ["Clicks", "239", "2.3%"], ["HIGHLIGHTS", "", "LOWLIGHTS"], ["Promoting the Tango App through GTKM, Beanstalk, and the Setup Checklist (DTM experiment) was effective in creating Tango App adoption.", "", "The IPDs on their own (ELM experiment) did not show an incremental benefit on Tango App adoption\nThe increase in Tango App adoption did not resulted in an improvement of 31d Retention"], ["NEXT STEPS & IMPLICATIONS", "", ""], ["Track 92d Retention. This metric should be available by March 21st\nTest if using Email as a channel to promote Tango App has a better impact compared to IPDs\nLimitation: If the customer opens the email in its mobile, the link to download the tango app will not work properly.\nDig into why more Importer Migrators were largely targeted by the ELM experience compared to the DTM experience.", "", ""]] | V6: Alt Date (slide 288): 10-16-2022 | Alt Product (slide 288): QuickBooks Online | Alt GET (slide 290): ed by the ELM experience compared to the DTM experience. | Alt TO (slide 290): non-Advance customers | Alt BY (slide 290): March 21st | Date: CSV-Current | W6: 287-290 | X6: Copy of Copy of CRM Analytics 2023 AC.pptx | Y6: ✅ ELM Roadmap | ⚠️ Results Report | Z6: non Advanced QBO DTM customers | AA6: non-Advance DTM QBO customers | AB6: Making them feel confident in their decision to migrate to QBO with an experience that is similar to what they are used to in Desktop.
A7: ELM-4941 | B7: QBO Upgrades Targeted Offer V2 | C7: 06-21-2023 | D7: GET: highly likely Quickbooks customers TO: Upgrades BY: offering targeted discounts based on price sensitivity | E7: IF: Offering discounts based on price sensitivity will optimize discount dollars & deliver significant incremental upgrades | F7: • SS > PLUS ESS > PLUS • SS > Plus upgrades sig. higher , factoring in discounts & | G7: Targeted discount based on price sensitivity were validated at scale for 6 cohorts and 3 price points • Retention sustained after discount promo period signalling right customers were targeted for upgrades • SS > Plus upgrades will break even in 1+ years and start delivering incremental revenue • NEXT STEPS & IMPLICATIONS • Align & rollout targeted discounts for SS > PLUS • Offer similar discount for ADV and/or call out higher $ savings in SKU selection ; Update targeting criteria to remove high ADV propensity candidates • Reevaluate discount bands for ESS > PLUS , i.e. >30% discount is lesser than monthly Essentials subscription cost • Test Trials or no cost upgrade for Essentials > PLUS | H7: Multiple iterations due to data issues , execution misses and other priorities like price increase • ESS > PLUS is ROI negative because of smaller lift , lesser Advanced upgrades and deep discounts | I7: upgrades will drive 82K lesser revenue in first 3 yrs. yrs. > PLUS POSITIVE BIZ IMPACT Detailed KPIs (SS > PLUS) KPIs TEST CON. Δ ITC Samples 84,081 84,193 Upgrades - PLUS (w/campaign) 1.4% 1.0% 357 143 Upgrades - ESS (w/campaign) 1.7% 1.8% -124 92 Upgrades - ADV (w/campaign) 0.4% 0.5% -53 86 Upgrades - ALL (ESS/PLUS/ADV) 3.5% 3.3% 180 107 Upgrades - PLUS (3 mo. retention) 88.8% 87.9% 0.8% 101 Upgrades - PLUS (post discount) 1.3% 0.9% 324 144 Upgrades - PLUS (4 mo. retention) 81.5% 82.8% -1.2% 99 Upgrades - PLUS Retained (post 4 mo.) 1.2% 0.8% 281 141 Est. incr. upgrade revenue in first year $16.4 $16.6 -$12,704 99 Est. incr. ESS upgrade revenue in first year $4.8 $5.3 -$35,531 92 Est. incr. PLUS upgrade revenue in first year $7.2 $6.4 $69,100 113 Est. incr. ADV upgrade revenue in first year $4.4 $4.9 -$46,274 89 Est. incr. upgrade rev. in first 2 yrs. $30.3 $29.3 $87,261 104 Est. incr. upgrade rev. in first 3 yrs. $40.5 $38.6 $163,377 105 PLUS Upgrades 3 mo. after campaign 0.40% 0.43% -23 94 Upgrade Retention ●B 3-month retention in PLUS plan of targeted discount cohort is comparable to group not receiving upgrade discount ●C 4-mo. retention (right measure for sizing full price impact) is trending down but upgrades sustained are significantly higher Estimated Incremental upgrade revenue ●D Plus upgrade rev. is significantly higher (+$69K) but ADV (-$46K) & ESS (-$35k) offset resulting in $12K lesser overall revenue • Payback period is relatively faster & targeted discount cohort E will generate incremental revenue after ~15 months Pull forwards ●F Upgrades after the campaign ended is directionally lower signalling discount driven pull forwardsHIGH Price Sens. MED Price Sens. LOW Price Sens. KPIs TEST CON. Δ ITC TEST CON. Δ ITC TEST CON. Δ ITC Samples 39,981 39,516 23,906 24,360 20,194 20,317 Upgrades - PLUS (w/campaign) 1.7% 1.1% 244 157 1.2% 0.8% 96 151 1.2% 1.1% 16 107 Upgrades - ESS (w/campaign) 1.6% 1.8% -104 86 1.6% 1.6% -1 100 2.0% 2.1% -20 95 Upgrades - ADV (w/campaign) 0.3% 0.4% -34 80 0.3% 0.4% -18 82 0.5% 0.5% -1 99 Upgrades - ALL (ESS/PLUS/ADV) 3.6% 3.3% 106 108 3.1% 2.8% 77 111 3.7% 3.7% -5 99 Upgrades - PLUS (4 mo. retention) 79.9% 81.8% -1.9% 98 82.0% 82.7% -0.7% 99 85.6% 84.6% 0 101 Upgrades - PLUS Retained (post 4 mo.) 1.3% 0.9% 187 153 1.0% 0.6% 77 150 1.0% 0.9% 16 109 Est. incr. upgrade rev. in first year $16.0 $16.9 -$34,758 95 $14.8 $14.1 $17,901 105 $19.1 $18.9 $3,177 101 Est. incr. ESS upgrade revenue in first year $4.5 $5.3 -$29,685 86 $4.6 $4.6 -$215 100 $5.7 $6.0 -$5,852 95 Est. incr. PLUS upgrade revenue in first year $7.5 $6.9 $24,363 109 $6.4 $5.0 $33,492 128 $7.5 $7.0 $10,47 3 107 Est. incr. ADV upgrade revenue in first year $4.0 $4.7 -$29,436 84 $3.8 $4.5 -$15,37 6 86 $5.9 $5.9 -$1,444 99 Est. incr. upgrade rev. in first 2 yrs. $29.8 $30.6 $31,517 103 $24.9 $26.9 $48,597 108 $33.5 $33.8 $5,429 101 Est. incr. upgrade rev. in first 3 yrs. $39.3 $41.3 $81,950 105 $32.8 $35.8 $71,997 109 $44.1 $44.5 $7,163 101 PLUS Upgrades 3 mo. after campaign 0.40% 0.38% 5 103 0.36% 0.44% -18 83 0.5% 0.5% -9 91 KPIs TEST CON. Δ ITC Samples 98,806 98,755 Upgrades - PLUS (w/campaign) 1.7% 1.5% 205 114 Upgrades - ADV (w/campaign) 0.5% 0.6% -46 92 Upgrades - ALL (ESS/PLUS/ADV) 2.2% 2.0% 159 108 Upgrades - PLUS (3 mo. retention) 92.6% 91.5% 1.1% 101 Upgrades - PLUS (post discount) 1.5% 1.3% 206 116 Upgrades - PLUS (4 mo. retention) 87.4% 86.9% 0.5% 101 Upgrades - PLUS Retained (post 4 mo.) 1.5% 1.3% 186 115 Est. incr. upgrade revenue in first year $10.5 $11.7 -117,580 90 Est. incr. PLUS upgrade revenue in first year $4.6 $5.3 -$72,558 86 Est. incr. ADV upgrade revenue in first year $6.0 $6.4 -$45,022 93 Est. incr. upgrade rev. in first 2 yrs. $20.9 $21.9 -$97,154 96 Est. incr. upgrade rev. in first 3 yrs. $28.7 $29.5 -$81,988 97 PLUS Upgrades 3 mo. after campaign 0.79% 0.83% -41 95 Detailed KPIs (ESS > PLUS) by Price Sensitivity ESS HIGH Price Sens. MED Price Sens. LOW Price Sens. KPIs TEST CON. Δ ITC TEST CON. Δ ITC TEST CON. Δ ITC Samples 37,043 37,039 30,742 30,577 30,970 31,190 Upgrades - PLUS (w/campaign) 1.7% 1.3% 149 131 1.3% 1.2% 38 110 1.9% 1.9% 19 103 Upgrades - PLUS (3 mo. retention) 93.5% 89.9% 3.7% 104 92.2% 90.6% 0 102 91.8% 93.3% 0 98 Upgrades - PLUS (post discount) 1.6% 1.2% 157 136 1.2% 1.1% 41 112 1.8% 1.8% 9 102 Upgrades - ADV (w/campaign) 0.5% 0.5% -1 99 0.4% 0.6% -47 73 0.7% 0.7% 2 101 Upgrades - ALL (ESS/PLUS/ADV) 2.2% 1.8% 148 122 1.7% 1.8% -9 98 2.6% 2.6% 22 103 Est. incr. upgrade revenue in year 1 $8.4 $10.2 -$63,503 83 $8.7 $10.8 -$63,08 0 81 $14.8 $14.5 $9,780 102 Est. incr. PLUS upgrade revenue in year 1 $3.0 $4.7 -$62,340 64 $3.9 $4.4 -$16,67 6 88 $7.0 $6.8 $6,941 103 Est. incr. ADV upgrade revenue in year 1 $5.4 $5.4 -$1,163 99 $4.9 $6.4 -$46,40 4 76 $7.8 $7.7 $2,839 101 Upgrades - PLUS (4 mo. retention) 86.7% 83.9% 2.9% 103 86.7% 86.3% 0.4% 100 88.5% 89.8% -1.2% 99 Upgrades - PLUS Retained (post 4 mo.) 1.5% 1.1% 143 135 1.2% 1.0% 34 111 1.7% 1.7% 10 102 Est. incr. upgrade rev. in first 2 yrs. $19.0 $18.4 -$20,061 97 $20.2 $17.2 -$93,71 6 85 $27.1 $27.7 $18,06 4 102 Est. incr. upgrade rev. in first 3 yrs. $25.5 $25.9 $12,317 101 $27.2 $23.4 -$116,6 10 86 $36.5 $37.3 $24,24 2 102 PLUS Upgrades 3 mo. after campaign 0.6% 0.6% 2 101 0.7% 0.7% -8 96 1.1% 1.2% Intuit Confi -33 dential and Pro 91 prietary RESULTS Targeted disco Align & rollout targeted discounts for SS > PLUS • Offer similar discount for ADV and/or call out higher $ savings in SKU selection ; Update targeting criteria to remove high ADV propensity candidates • Reevaluate discount bands for ESS > PLUS , i.e. >30% discount is lesser than monthly Essentials subscription cost • Test Trials or no cost upgrade for Essentials > PLUS Global Business Solution | J7: QBO | K7: IPD; Email; Sales; Landing Page | L7: Trending Positive | M7: ROI NEGATIVE lesser ADV upgrades payback is ~15 months & Targeted discounts delivered sig. higher SS > PLUS upgrades (143 ITC , + 357) & will deliver +170K revenue by end of year 3 ; Roll out estimate : incremental revenue estimate for first 3 yrs. is 170 K 900 incr. Plus Upgrades & +430K incremental revenue over 3 yrs. ESS > Plus sig. higher , discounts & lesser ADV Targeted discounts delivered sig. higher ESS > PLUS upgrades (114 ITC , + upgrades will drive 82K lesser revenue in first 3 yrs. 205) but will deliver 82K lesser revenue by end of year 3 | U7: [["Wrap Report"], ["ELM -4941"], ["", "", "", "", "", "ade -", "", "", "", "", ""], ["", "", "", "", "ESS > PLUS", "", "", "", "", "", ""], ["", "Business Impact: POSITIVE POSITIVE\nBIZ IMPACT ROI NEGATIVE\nTargeted discounts delivered sig. higher SS > PLUS u\n357) & will deliver +170K revenue by end of year 3 ;\n900 incr. Plus Upgrades & +430K incremental rev\nTargeted discounts delivered sig. higher ESS > PLUS\n205) but will deliver 82K lesser revenue by end of ye", "", "", "", "pgrades (143 ITC , +\nRoll out estimate :\nenue over 3 yrs.", "", "", "", "", ""], ["", "", "", "", "POSITIVE\nROI NEGATIVE", "", "", "", "", "", ""], ["", "", "", "", "", "upgrades (114 ITC , +\nar 3", "", "", "", "", ""], ["Objective\nGet highly likely Quickbooks customers\nTo upgrade to Quickbooks Plus\nBy offering targeted discounts based on price sensitivity\nHypothesis\nOffering discounts based on price sensitivity will optimize\ndiscount dollars & deliver significant incremental upgrades\nResults", "", "", "", "", "", ""], ["KPIs", "TEST", "", "CON.", "Δ", "", "ITC"], ["A SS > PLUS (N=88K/variant)", "", "", "", "", "", ""], ["Upgrades - PLUS (w/campaign)", "1.4%", "", "1.0%", "357", "", "143"], ["Est. incr. upgrade rev. in first 3 yrs.", "$40.5", "", "$38.6", "$163,377", "", "105"], ["B\nESS > PLUS (N=98k/variant)", "", "", "", "", "", ""], ["Upgrades - PLUS (w/campaign)", "1.7%", "", "1.5%", "205", "", "114"], ["Est. incr. upgrade rev. in first 3 yrs.", "$28.7", "", "$29.5", "-$81,988", "", "97"], ["Learnings & Implications\n●A SS > Plus upgrades sig. higher , factoring in discounts &\nlesser ADV upgrades payback is ~15 months &\nincremental revenue estimate for first 3 yrs. is 170 K\n●B ESS > Plus sig. higher , discounts & lesser ADV", "", "", "", "", "", ""], ["", "", "", "", "", "yrs.\ns G3ro4up8", ""], ["SS > PLUS"], ["POSITIVE\nBIZ IMPACT"], ["Detailed KPIs (SS > PLUS)", ""], ["KPIs", "TEST", "CON.", "Δ", "ITC"], [" Samples", "84,081", "84,193", "", ""], ["Upgrades - PLUS (w/campaign)", "1.4%", "1.0%", "357", "143"], ["Upgrades - ESS (w/campaign)", "1.7%", "1.8%", "-124", "92"], ["Upgrades - ADV (w/campaign)", "0.4%", "0.5%", "-53", "86"], ["Upgrades - ALL (ESS/PLUS/ADV)", "3.5%", "3.3%", "180", "107"], ["Upgrades - PLUS (3 mo. retention)", "88.8%", "87.9%", "0.8%", "101"], ["Upgrades - PLUS (post discount)", "1.3%", "0.9%", "324", "144"], ["Upgrades - PLUS (4 mo. retention)", "81.5%", "82.8%", "-1.2%", "99"], ["Upgrades - PLUS Retained (post 4 mo.)", "1.2%", "0.8%", "281", "141"], ["Est. incr. upgrade revenue in first year", "$16.4", "$16.6", "-$12,704", "99"], ["Est. incr. ESS upgrade revenue in first year", "$4.8", "$5.3", "-$35,531", "92"], ["Est. incr. PLUS upgrade revenue in first year", "$7.2", "$6.4", "$69,100", "113"], ["Est. incr. ADV upgrade revenue in first year", "$4.4", "$4.9", "-$46,274", "89"], ["Est. incr. upgrade rev. in first 2 yrs.", "$30.3", "$29.3", "$87,261", "104"], ["Est. incr. upgrade rev. in first 3 yrs.", "$40.5", "$38.6", "$163,377", "105"], ["PLUS Upgrades 3 mo. after campaign", "0.40%", "0.43%", "-23", "94"], ["Upgrade Retention\n●B 3-month retention in PLUS plan of targeted discount cohort is\ncomparable to group not receiving upgrade discount\n●C 4-mo. retention (right measure for sizing full price impact) is trending\ndown but upgrades sustained are significantly higher"], ["Estimated Incremental upgrade revenue\n●D Plus upgrade rev. is significantly higher (+$69K) but ADV (-$46K)\n& ESS (-$35k) offset resulting in $12K lesser overall revenue\n● Payback period is relatively faster & targeted discount cohort\nE will generate incremental revenue after ~15 months"], ["Pull forwards\n●F Upgrades after the campaign ended is directionally lower\nsignalling discount driven pull forwards\n"], ["", "HIGH Price Sens.", "", "", "", "MED Price Sens.", "", "", "", "LOW Price Sens.", "", "", ""], ["KPIs", "TEST", "CON.", "Δ", "ITC", "TEST", "CON.", "Δ", "ITC", "TEST", "CON.", "Δ", "ITC"], [" Samples", "39,981", "39,516", "", "", "23,906", "24,360", "", "", "20,194", "20,317", "", ""], ["Upgrades - PLUS (w/campaign)", "1.7%", "1.1%", "244", "157", "1.2%", "0.8%", "96", "151", "1.2%", "1.1%", "16", "107"], ["Upgrades - ESS (w/campaign)", "1.6%", "1.8%", "-104", "86", "1.6%", "1.6%", "-1", "100", "2.0%", "2.1%", "-20", "95"], ["Upgrades - ADV (w/campaign)", "0.3%", "0.4%", "-34", "80", "0.3%", "0.4%", "-18", "82", "0.5%", "0.5%", "-1", "99"], ["Upgrades - ALL (ESS/PLUS/ADV)", "3.6%", "3.3%", "106", "108", "3.1%", "2.8%", "77", "111", "3.7%", "3.7%", "-5", "99"], ["Upgrades - PLUS (4 mo. retention)", "79.9%", "81.8%", "-1.9%", "98", "82.0%", "82.7%", "-0.7%", "99", "85.6%", "84.6%", "0", "101"], ["Upgrades - PLUS Retained (post 4 mo.)", "1.3%", "0.9%", "187", "153", "1.0%", "0.6%", "77", "150", "1.0%", "0.9%", "16", "109"], ["Est. incr. upgrade rev. in first year", "$16.0", "$16.9", "-$34,758", "95", "$14.8", "$14.1", "$17,901", "105", "$19.1", "$18.9", "$3,177", "101"], ["Est. incr. ESS upgrade revenue in first year", "$4.5", "$5.3", "-$29,685", "86", "$4.6", "$4.6", "-$215", "100", "$5.7", "$6.0", "-$5,852", "95"], ["Est. incr. PLUS upgrade revenue in first year", "$7.5", "$6.9", "$24,363", "109", "$6.4", "$5.0", "$33,492", "128", "$7.5", "$7.0", "$10,47\n3", "107"], ["Est. incr. ADV upgrade revenue in first year", "$4.0", "$4.7", "-$29,436", "84", "$3.8", "$4.5", "-$15,37\n6", "86", "$5.9", "$5.9", "-$1,444", "99"], ["Est. incr. upgrade rev. in first 2 yrs.", "$29.8", "$30.6", "$31,517", "103", "$24.9", "$26.9", "$48,597", "108", "$33.5", "$33.8", "$5,429", "101"], ["Est. incr. upgrade rev. in first 3 yrs.", "$39.3", "$41.3", "$81,950", "105", "$32.8", "$35.8", "$71,997", "109", "$44.1", "$44.5", "$7,163", "101"], ["PLUS Upgrades 3 mo. after campaign", "0.40%", "0.38%", "5", "103", "0.36%", "0.44%", "-18", "83", "0.5%", "0.5%", "-9", "91"], ["KPIs", "TEST", "CON.", "Δ", "ITC"], [" Samples", "98,806", "98,755", "", ""], ["Upgrades - PLUS (w/campaign)", "1.7%", "1.5%", "205", "114"], ["Upgrades - ADV (w/campaign)", "0.5%", "0.6%", "-46", "92"], ["Upgrades - ALL (ESS/PLUS/ADV)", "2.2%", "2.0%", "159", "108"], ["Upgrades - PLUS (3 mo. retention)", "92.6%", "91.5%", "1.1%", "101"], ["Upgrades - PLUS (post discount)", "1.5%", "1.3%", "206", "116"], ["Upgrades - PLUS (4 mo. retention)", "87.4%", "86.9%", "0.5%", "101"], ["Upgrades - PLUS Retained (post 4 mo.)", "1.5%", "1.3%", "186", "115"], ["Est. incr. upgrade revenue in first year", "$10.5", "$11.7", "-117,580", "90"], ["Est. incr. PLUS upgrade revenue in first year", "$4.6", "$5.3", "-$72,558", "86"], ["Est. incr. ADV upgrade revenue in first year", "$6.0", "$6.4", "-$45,022", "93"], ["Est. incr. upgrade rev. in first 2 yrs.", "$20.9", "$21.9", "-$97,154", "96"], ["Est. incr. upgrade rev. in first 3 yrs.", "$28.7", "$29.5", "-$81,988", "97"], ["PLUS Upgrades 3 mo. after campaign", "0.79%", "0.83%", "-41", "95"], ["Detailed KPIs (ESS > PLUS) by Price Sensitivity", "", "", "", "", "", "", "", "", "", "", "", "", "", ""], ["ESS", "HIGH Price Sens.", "", "", "", "MED Price Sens.", "", "", "", "LOW Price Sens.", "", "", "", "", ""], ["KPIs", "TEST", "CON.", "Δ", "ITC", "TEST", "CON.", "Δ", "ITC", "TEST", "CON.", "", "Δ", "ITC", ""], [" Samples", "37,043", "37,039", "", "", "30,742", "30,577", "", "", "30,970", "31,190", "", "", "", ""], ["Upgrades - PLUS (w/campaign)", "1.7%", "1.3%", "149", "131", "1.3%", "1.2%", "38", "110", "1.9%", "1.9%", "", "19", "103", ""], ["Upgrades - PLUS (3 mo. retention)", "93.5%", "89.9%", "3.7%", "104", "92.2%", "90.6%", "0", "102", "91.8%", "93.3%", "", "0", "98", ""], ["Upgrades - PLUS (post discount)", "1.6%", "1.2%", "157", "136", "1.2%", "1.1%", "41", "112", "1.8%", "1.8%", "", "9", "102", ""], ["Upgrades - ADV (w/campaign)", "0.5%", "0.5%", "-1", "99", "0.4%", "0.6%", "-47", "73", "0.7%", "0.7%", "", "2", "101", ""], ["Upgrades - ALL (ESS/PLUS/ADV)", "2.2%", "1.8%", "148", "122", "1.7%", "1.8%", "-9", "98", "2.6%", "2.6%", "", "22", "103", ""], ["Est. incr. upgrade revenue in year 1", "$8.4", "$10.2", "-$63,503", "83", "$8.7", "$10.8", "-$63,08\n0", "81", "$14.8", "$14.5", "", "$9,780", "102", ""], ["Est. incr. PLUS upgrade revenue in year 1", "$3.0", "$4.7", "-$62,340", "64", "$3.9", "$4.4", "-$16,67\n6", "88", "$7.0", "$6.8", "", "$6,941", "103", ""], ["Est. incr. ADV upgrade revenue in year 1", "$5.4", "$5.4", "-$1,163", "99", "$4.9", "$6.4", "-$46,40\n4", "76", "$7.8", "$7.7", "", "$2,839", "101", ""], ["Upgrades - PLUS (4 mo. retention)", "86.7%", "83.9%", "2.9%", "103", "86.7%", "86.3%", "0.4%", "100", "88.5%", "89.8%", "", "-1.2%", "99", ""], ["Upgrades - PLUS Retained (post 4 mo.)", "1.5%", "1.1%", "143", "135", "1.2%", "1.0%", "34", "111", "1.7%", "1.7%", "", "10", "102", ""], ["Est. incr. upgrade rev. in first 2 yrs.", "$19.0", "$18.4", "-$20,061", "97", "$20.2", "$17.2", "-$93,71\n6", "85", "$27.1", "$27.7", "", "$18,06\n4", "102", ""], ["Est. incr. upgrade rev. in first 3 yrs.", "$25.5", "$25.9", "$12,317", "101", "$27.2", "$23.4", "-$116,6\n10", "86", "$36.5", "$37.3", "", "$24,24\n2", "102", ""], ["PLUS Upgrades 3 mo. after campaign", "0.6%", "0.6%", "2", "101", "0.7%", "0.7%", "-8", "96", "1.1%", "", "1.2%\nIntuit Confi", "-33\ndential and Pro", "91\nprietary", ""], ["RESULTS\nTargeted disco"], ["HIGHLIGHTS", "", "LOWLIGHTS"], ["● Targeted discount based on price sensitivity were\nvalidated at scale for 6 cohorts and 3 price points\n● Retention sustained after discount promo period\nsignalling right customers were targeted for\nupgrades\n● SS > Plus upgrades will break even in 1+ years and\nstart delivering incremental revenue", "", "● Multiple iterations due to data issues , execution misses\nand other priorities like price increase\n● ESS > PLUS is ROI negative because of smaller lift , lesser\nAdvanced upgrades and deep discounts"], ["NEXT STEPS & IMPLICATIONS", "", ""], ["● Align & rollout targeted discounts for SS > PLUS\n● Offer similar discount for ADV and/or call out higher $ savings in SKU selection ; Update targeting criteria to remove high\nADV propensity candidates\n● Reevaluate discount bands for ESS > PLUS , i.e. >30% discount is lesser than monthly Essentials subscription cost\n● Test Trials or no cost upgrade for Essentials > PLUS", "", ""]] | V7: Alt Product (slide 348): QuickBooks | Alt TO (slide 348): mers | Alt GET (slide 349): ed discount cohort is | Alt TO (slide 349): group not receiving upgrade discount | Alt BY (slide 349): incremental PLUS (357) & offset by Essentials (-124) / Advanced | Alt BY (slide 350): Price Sensitivity | Alt GET (slide 351): ed discount cohort is | Alt TO (slide 351): group not receiving upgrade discount | Alt BY (slide 351): Upgrades - PLUS (w/campaign) 1.7% 1.5% 205 114 A | Alt BY (slide 352): Price Sensitivity | Alt GET (slide 353): ed discounts for SS > Plus delivered positive | Alt TO (slide 353): data issues , execution misses | Date source: CSV - Current Target Launch Date | Name source: CSV | W7: 347-353 | X7: Copy of FY'25_ CRM Analytics Monthly Experiment_Notebook_AC.pdf | Y7: ✅ ELM Roadmap | ⚠️ Results Report | Z7: highly likely Quickbooks customers | AA7: Upgrades | AB7: offering targeted discounts based on price sensitivity
A8: ELM-5379 | B8: Tax Biz Partnership email with CG | C8: 02-06-2023 | D8: GET: ing QBO customers (S Corp, Multi-Member LLC, Partnerships) with an email to introduce Turbox Tax Live full service and DIY product to drive Business TT take rate. BY: sending an email introducing TurboTax features | E8: IF: THEN: We will see a positive take rate in treatment group with a discernable pattern of attributes with interested customers. (Inferred for review) | F8: • | Turbo Tax take rate (Full Service + Assisted) is directionally higher in treatment than control However, the lift units are pretty small due to that TaxBiz is a new product which just has just been launched since the end of January of 2023 Email Open rate is well above benchmark at 134 ITB Email Click rate is well above benchmark at 112 ITB Email Unsub is a little bit higher than benchmark might because we did not target high TT propensity users Even though our email content was only created for Biz products, it might also have a eco effect for the awareness of personal products. • Email shows higher take rate in treatment group than control. • The take rates for treatment and control group were flat for past 4 years (without ELM email) but directional positive for this year (with ELM email). | G8: Treatment group shows higher take rate than control Email engagement is pretty well • NEXT STEPS & IMPLICATIONS • Personalize emails and target TT high propensity users with promo QBLive + TT Biz bundle (i.e buy QBLive FS, get a 10% off discount for TTBiz FS etc) to improve both QBL and TTB GNS • KPIs TEST CON. • Assignments 86,787 22,003 • Turbo Tax Take rate (2018) 2.84% 2.93% • Turbo Tax Take rate (2019) 3.00% 3.13% • Turbo Tax Take rate (2020) 3.19% 3.35% • Turbo Tax Take rate (2021) 3.51% 3.59% • Turbo Tax Take rate (2022) 0.91% 0.89% | H8: Take rate in treatment group is not stat. Sig QBO audience is not able to expand more (Business Entity) • Δ ITC ELM Incentive • (80:20) • -114 97 NO • -155 96 NO • -182 95 NO • -115 98 NO • 7 102 Email | I8: Personalize emails and target TT high propensity users with promo QBLive + TT Biz bundle (i.e buy QBLive FS, get a 10% off discount for TTBiz FS etc) to improve both QBL and TTB GNS KPIs TEST CON. Δ ITC ELM Incentive Assignments 86,787 22,003 (80:20) Turbo Tax Take rate (2018) 2.84% 2.93% -114 97 NO Turbo Tax Take rate (2019) 3.00% 3.13% -155 96 NO Turbo Tax Take rate (2020) 3.19% 3.35% -182 95 NO Turbo Tax Take rate (2021) 3.51% 3.59% -115 98 NO Turbo Tax Take rate (2022) 0.91% 0.89% 7 102 Email | J8: QBO | K8: Email | L8: Not found (Inferred for review) | U8: [["HYPO\n-THESIS", "We will see a positive take rate in treatment group with a discernable pattern of attributes with interested customers.", "", "", "", ""], ["KPIs", "TEST", "CON.", "Δ", "ITC"], ["Assignments", "86,787", "22,003", "(80:20)", ""], ["Turbo Biz (FS +Assisted)", "15", "2", "7 (Scaled)*", ""], ["Turbo Biz (FS +Assisted)", "0.02%", "0.01%", "0.01%", "190"], ["Email ENGAGEMENT", "", "", "", "", "", "", "", "", ""], ["Cohort", "Email", "", "", "", "", "", "", "", ""], ["", "Unique Sends*", "Unique Opens", "Open rate %", "ITB", "Unique Clicks", "CTR", "ITB", "Unsub %", "ITB"], ["Treatment", "75.5K", "26.8K", "35.5%", "134", "422.6", "0.56%", "112", "0.18%", "165"], ["Control", "No comms", "", "", "", "", "", "", "", ""], ["Email XSell Benchmark*", "", "", "27%", "", "", "0.5%", "", "0.11%", ""], ["HIGHLIGHTS", "LOWLIGHTS"], ["Treatment group shows higher take rate than control\nEmail engagement is pretty well", "Take rate in treatment group is not stat. Sig\nQBO audience is not able to expand more (Business Entity)"], ["NEXT STEPS & IMPLICATIONS", ""], ["Personalize emails and target TT high propensity users with promo\nQBLive + TT Biz bundle (i.e buy QBLive FS, get a 10% off discount for TTBiz FS etc) to improve both QBL and TTB GNS", ""], ["KPIs", "TEST", "CON.", "Δ", "ITC", "ELM Incentive"], ["Assignments", "86,787", "22,003", "(80:20)", "", ""], ["Turbo Tax Take rate (2018)", "2.84%", "2.93%", "-114", "97", "NO"], ["Turbo Tax Take rate (2019)", "3.00%", "3.13%", "-155", "96", "NO"], ["Turbo Tax Take rate (2020)", "3.19%", "3.35%", "-182", "95", "NO"], ["Turbo Tax Take rate (2021)", "3.51%", "3.59%", "-115", "98", "NO"], ["Turbo Tax Take rate (2022)", "0.91%", "0.89%", "7", "102", "Email"]] | V8: Alt GET (slide 221): high TT propensity users | Alt GET (slide 222): TT high propensity users with promo | Alt TO (slide 222): expand more (Business Entity) | TO repaired: truncated 'customers' prefix restored | Date: CSV-Current | W8: 219-223 | X8: Copy of Copy of CRM Analytics 2023 AC.pptx | Y8: ✅ ELM Roadmap | ⚠️ Results Report | Z8: ing QBO customers (S Corp, Multi-Member LLC, Partnerships) with an email to introduce Turbox Tax Live full service and DIY product to drive Business TT take rate. | AA8: Customers (S Corp, Multi-Member LLC, Partnerships) with an email to introduce Turbox Tax Live full service and DIY product to drive Business TT take rate. | AB8: sending an email introducing TurboTax features
