Workbook

Sheet Campaigns
A1: Campaign ID | B1: Campaign Name | C1: Date of Campaign Launch | D1: Strategic Framework - GET | E1: Strategic Framework - TO | F1: Strategic Framework - BY | G1: Strategic Framework (Full GET/TO/BY) | H1: Hypothesis (IF/THEN) | I1: Learning | J1: Product | K1: Channels Included | L1: Campaign Success Status | M1: Business Impact | N1: Wrap Report Link | O1: Primary Experiment Metric 1 | P1: ITC - 1 | Q1: Primary Experiment Metric 2 | R1: ITC - 2 | S1: Primary Experiment Metric 3 | T1: ITC - 3 | U1: Table Data | V1: Misc | W1: Slide Number(s) | X1: Slide Deck Name
A2: ELM-8343 | B2: [DIWM] Test 2-Click Conversion on IPDs | C2: 09-15-2025 | D2: Existing QBO customer | E2: PIC TIME | F2: Reducing the cognitive load on customers by taking them directly to the | G2: GET: Existing QBO customer | TO: PIC TIME | BY: Reducing the cognitive load on customers by taking them directly to the | H2: If we send customers straight to the billing page, Then we reduce the | I2: Repository Upgrade - ELM 6651 12 Min Manasa / Sowmya Global Business Solutions Group 6 & Implications 0d-90d assigns 4,373 4,162 ●A +8.3% lift in DIWM SU for Accountant Attached 31D DIWM SU 0.57% 0.65% 113 NA (366d+) users (ITC = 108, 94% confidence) 91d-365d assigns 25,412 25,493 Accountant ●B +5% lift for Non-Accountant Attached (366d+) Attached 31D DIWM SU 0.31% 0.30% 96 NA users (ITC = 105) 366d+ assigns 411,510 413,420 A 31D DIWM SU 0.21% 0.23% 108 94% 0d-90d assigns 5,271 5,269 31D DIWM SU 2.28% 2.16% 95 Non 91d-365d assigns 19,488 19,448 Accountant 31D DIWM SU 0.79% 0.78% 98 B Attached 366d+ assigns 216,138 215,723 31D DIWM SU 0.30% 0.31% 105 71% This, Indicates “fewer steps to purchase” or simplified messaging resonates most with mature, embedded QBO users who are already familiar with workflows., Minimal or negative movement in <1 year cohorts suggests need for differentiated onboarding or guidance messaging for newer users. Global Business Solutions Group 9 Segment qbo_age treatment Imp. Clicks CTR Δ ITC ● Accountant Attached: All cohorts (0–90d, 91–365d, 0d-90d Control 2,681 22 0.82% A A 366d+) show lower CTR and ITC, indicating weaker 0d-90d Treatment 2,581 14 0.54% -0.28% 66 response to treatment. Accountant 366d+ Control 244,169 1,180 0.48% Attached 366d+ Treatment 245,789 989 0.40% -0.08% 83 B● Non-Accountant Attached: 91–365d and 366d+ 91d-365d Control 16,457 60 0.36% cohorts see small CTR and ITC gains, showing positive 91d-365d Treatment 16,614 50 0.30% -0.06% 83 treatment lift. 0d-90d Control 4,916 424 8.62% B 0d-90d Treatment 4,918 377 7.67% -0.96% 89 C● Overall: Treatment underperforms for Accountant Non Accountant 366d+ Control 200,472 15,319 7.64% Attached users but delivers modest uplift for Attached 366d+ Treatment 201,407 15,512 7.70% 0.06% 101 Non-Accountant Attached users. 91d-365d Control 17,951 1,214 6.76% 91d-365d Treatment 17,949 1,234 6.88% 0.11% 102 IPD Segment Cohort Imp. Clicks CTR Δ ITC Accountant Control 244,169 1,180 0.48% Attached Treatment 245,789 989 0.40% -0.08% 83 C Non Accountant Control 200,472 15,319 7.64% Attached Treatment 201,407 15,512 7.70% 0.06% 101 Global Business Solutions Group 11 into “Streamline Purchase” pillar of FODE experiments to guide future activation tests. ● Monitor eco-revenue & trial to gns conversion to validate long-term monetization impact post trial. Global Business Solutions Group 12 | J2: QBO | K2: IPD | L2: Positive | Results: 5.1 MEASURE: Complete | M2: Positive Biz Impact | 107 ITC-1 | N2: https://docs.google.com/presentation/d/1eCpJUw73_gHKVsWXHbX-LjM0QESG_Df0_YDTzfesHS4/edit?usp=sharing | O2: GNS/GNA | P2: 107 | U2: [[""], ["AGENDA"], ["TOPIC", "", "TIME"], ["1.Live - 2 Click Conversion - ELM 8343\nAneesh", "", "12 Min"], ["2.Tax - Zero State Page Optimization - ELM-8355\nAneesh", "", "12 Min"], ["3.TCO Dry Tests - ELM-8764, ELM-8929, ELM-8777\nAndre", "", "20 Min"], ["4.Insights Repository Upgrade - ELM 6651\nManasa / Sowmya", "", "12 Min"], ["Global Business Solutio", "ns Group", "6"], ["WRAP REPORT", "", ""], ["ELM - 8343- [FODE / DIW\nTest 2-Click", "M]", ""], ["Link", ""], ["", "Link"], ["", "Link"], ["", "Template v6.0 Updated Sept 2025\nGLOBAL BGUlSoIbNaEl SBSus SinOeLsUs SToIOluNtioSn Gs RGOroUuPp", "", ""], ["", "", "", "7"], ["", "", "GLOBAL BGUlSoIbNaEl SBSus SinOeLsUs SToIOluNtioSn Gs RGOroUuPp", ""], ["", "", "", ""], ["ELM EXPERIMENT RESULTS\n2-Click Conversion for IPDs\nTesting a new CTA directing DIWM free trial IPDs straight to\nthe billing flow to streamline activation. Run across digital\nchannels with simplified targeting to reduce friction and boost\ntrial starts.\nControl Experience\nIPD Clicked Landing Page Billing Page\nIPD Clicked Billing Page\nTreatment Experience\nBusiness Impact: POSITIVE\nIMPACT\n● Removing Landing Page visit after IPD Click has delivered stat sig results\nfor 366d+ QBO Customers across Non Accnt Attached and Accnt\nAttached with an estimated DIWM Signups (107 ITC, +70).\n● Roll out estimate: ~775 incremental DIWM GNS annually (assuming\n67% Conversion from trial) with +$300K incremental annual revenue.", "", "", "PRODUCTS: QBLive ● DRIVER: Name ● QB: ELM-8343 ● SOT: Deck ● DATES: ##-##-## to ##-##-##", "", "", "", "", "", "", "", "", ""], ["", "", "", "", "Objective\nGet Existing QBO customer\nTo Sign up for the consent up front DIWM free trial\nBy Reducing the cognitive load on customers by taking them directly to the\nfree trial billing page.\nHypothesis\nIf we send customers straight to the billing page, Then we reduce the\nnumber of steps to start their trial-- Increasing Trial Starts By 10%\nResults - 09/15/2025 - 09/30/2025", "", "", "", "", "", "", "", ""], ["", "", "", "", "Segment", "KPIs", "TEST", "", "CON.", "Δ", "ITC", "Prob. (T>C)", ""], ["", "", "", "", "", "", "", "", "", "", "", "", ""], ["", "", "", "", "Accountant\nAttached", "Assigns", "456,471", "", "454,727", "", "", "", ""], ["", "", "", "", "", "31D DIWM SU", "0.24%", "", "0.22%", "70", "107", "85%", ""], ["", "", "", "", "", "31D Eco rev", "$166", "", "$166", "$0.0", "100", "", ""], ["", "", "", "", "Non\nAccountant\nAttached", "Assigns", "249,208", "", "249,786", "", "", "", ""], ["", "", "", "", "", "31D DIWM SU", "0.39%", "0.39%", "0.39%", "8", "101", "", ""], ["", "", "", "", "", "", "", "", "", "", "", "", ""], ["", "", "", "", "", "31D Eco rev", "$149", "", "$149", "$0.0", "100", "", ""], ["", "", "", "", "", "", "", "", "", "", "", "", ""], ["", "", "", "", "Learnings & Implications\nA ● Overall DIWM SU: +7% lift vs. control ( Prob =\n85%).Revenue flat indicated improved activation not yet\ntranslating into higher monetization.\nB● DIWM SU: +8 Unit improvement (ITC = 101) —\nstatistically flat. Eco Rev ($149) unchanged.\nGlobal Business Solutions Group 8", "", "", "", "", "", "", "", ""], ["", "Business Impact: POSITIVE\nIMPACT\n● Removing Landing Page visit after IPD Click has delivered stat sig results\nfor 366d+ QBO Customers across Non Accnt Attached and Accnt\nAttached with an estimated DIWM Signups (107 ITC, +70).\n● Roll out estimate: ~775 incremental DIWM GNS annually (assuming\n67% Conversion from trial) with +$300K incremental annual revenue.", "", "", "", "", "", "", "", "", "", "", ""], ["", "", "t\ning\nue.", "", "", "", "", "", "", "", "", "", ""], ["", "", "", "", "", "", "", "", "", "", "", "", ""], ["ELM EXPERIMENT RESULTS"], ["2-Click Conve"], ["", "Control Experience"], ["IPD Clicked Landing Page Billing Page", ""], ["IPD Clicked", "Landing Page", "Billing Page"], ["IPD Clicked Billing Page", ""], ["", "Treatment Experience"], ["IPD Clicked", "Billing Page"], ["Global Business Solutio", "ns Group", "8"], ["", "Call Outs: A D G"], ["FLAT\nIMPACT", ""], [""], ["ELM EXPERIMENT RESULTS"], ["cohort", "QBO Age", "KPIs", "Control", "Treatment", "ITC", "Prob. (T>C)"], ["Accountant\nAttached", "0d-90d", "assigns", "4,373", "4,162", "", ""], ["", "", "31D DIWM SU", "0.57%", "0.65%", "113", "NA"], ["", "91d-365d", "assigns", "25,412", "25,493", "", ""], ["", "", "31D DIWM SU", "0.31%", "0.30%", "96", "NA"], ["", "366d+", "", "", "", "", ""], ["", "", "assigns", "411,510", "413,420", "", "A"], ["", "", "", "", "", "", ""], ["", "", "31D DIWM SU", "0.21%", "0.23%", "108", "94%"], ["Non\nAccountant\nAttached", "0d-90d", "assigns", "5,271", "5,269", "", ""], ["", "", "31D DIWM SU", "2.28%", "2.16%", "95", ""], ["", "91d-365d", "assigns", "19,488", "19,448", "", ""], ["", "", "31D DIWM SU", "0.79%", "0.78%", "98", "B"], ["", "", "", "", "", "", ""], ["", "366d+", "", "", "", "", ""], ["", "", "assigns", "216,138", "215,723", "", ""], ["", "", "31D DIWM SU", "0.30%", "0.31%", "105", "71%"], ["Global Business Solutio", "ns Group", "9"], ["Results: POSITIVE DIR. POSITIVE\nIMPACT IMPACT", "", "Call Outs: A D G"], ["", "FLAT\nIMPACT", ""], [""], ["ELM EXPERIMENT RESULTS"], ["", "Accountant Attached\nnel\n41%\nloss", "", "", "Non Accountant Attached\n7%\nloss", "Non Accountant Attached", ""], ["Control Fun", "nel", "", "", "", "", ""], ["", "", "", "", "", "", ""], ["", "", "", "", "B", "", ""], ["Test Funn", "el", "", "", "+7.2% +29%\n7%\nloss", "", ""], ["", "", "+69%", "", "", "", "+29%"], ["", "A ● Accountant Attached users, with +13% uplift in “V", "", "", "Signup” and a +69% uplift in “Clicked to 3ID Signup,” indica", "", ""], ["Global Business Solutio", "ns Group", "10"], ["Results: POSITIVE DIR. POSITIVE\nIMPACT IMPACT", "FLAT\nIMPACT", "Call Outs: A D G"], [""], ["ELM EXPERIMENT RESULTS"], ["Segment", "qbo_age", "treatment", "IPD", "", "", "", ""], ["", "", "", "Imp.", "Clicks", "CTR", "Δ", "ITC"], ["Accountant\nAttached", "0d-90d", "Control", "2,681", "22", "0.82%", "", ""], ["", "", "", "", "", "", "", ""], ["", "0d-90d", "Treatment", "2,581", "14", "0.54%", "-0.28%", "66"], ["", "366d+", "Control", "244,169", "1,180", "0.48%", "", ""], ["", "366d+", "Treatment", "245,789", "989", "0.40%", "-0.08%", "83"], ["", "91d-365d", "Control", "16,457", "60", "0.36%", "", ""], ["", "91d-365d", "Treatment", "16,614", "50", "0.30%", "-0.06%", "83"], ["Non Accountant\nAttached", "0d-90d", "Control", "4,916", "424", "8.62%", "", ""], ["", "", "", "", "", "", "", ""], ["", "0d-90d", "Treatment", "4,918", "377", "7.67%", "-0.96%", "89"], ["", "366d+", "Control", "200,472", "15,319", "7.64%", "", ""], ["", "366d+", "Treatment", "201,407", "15,512", "7.70%", "0.06%", "101"], ["", "91d-365d", "Control", "17,951", "1,214", "6.76%", "", ""], ["", "91d-365d", "Treatment", "17,949", "1,234", "6.88%", "0.11%", "102"], ["Segment", "Cohort", "IPD", "", "", "", ""], ["", "", "Imp.", "Clicks", "CTR", "Δ", "ITC"], ["Accountant\nAttached", "Control", "244,169", "1,180", "0.48%", "", ""], ["", "Treatment", "245,789", "989", "0.40%", "-0.08%", "83"], ["Non Accountant\nAttached", "Control", "200,472", "15,319", "7.64%", "", "C"], ["", "Treatment", "201,407", "15,512", "7.70%", "0.06%", "101"], ["Global Business Solutio", "ns Group", "11"], ["Results: POSITIVE DIR. POSITIVE\nIMPACT IMPACT", "", "Call Outs: A D G"], ["", "FLAT\nIMPACT", ""], [""], ["ELM EXPERIMENT RESULTS"], [""], ["The 2-Click IPD experience delivered measurable lift in trial conversion for established QBO customers, validating\nsimplified activation as a lever for future purchase flows."], ["HIGHLIGHTS", "", "LOWLIGHTS"], ["● 2-Click IPD flow delivered +7 % overall DIWM sign-ups vs\ncontrol (ITC 107 / Prob 85 %) — stat sig for 366 d+ cohorts\nacross both Accountant & Non-Accountant segments.\n● Accountant Attached (366 d+) +8.3 % lift (ITC 108) and\nNon-Accountant Attached (366 d+) +5 % lift (ITC 105),\nconfirming friction reduction improves trial activation\n● Funnel data shows strong last-step uplift (+69 % Accountant\nAttached, +29 % Non-Accountant) → simplified flow drives\nmore completions", "", "● Accountant-Attached CTR dropped (<90 ITC) across all age bands\n(0–90 d → 366 d+) indicating weaker top-of-funnel response.\n● Revenue outcomes flat so far — activation improved, but monetization\nimpact not yet realized.\n● Newer (< 1 year) QBO users showed minimal or negative response,\nsignaling need for differentiated onboarding messaging."], ["", "", ""], ["NEXT STEPS & IMPLICATIONS", "", ""], ["● Introduce 2-Click IPD across relevant journeys to further boost tax trial starts.\n● Expand to other products for tenured (366 d+) customers where flow simplification has proven effective.\n● Feed learning into “Streamline Purchase” pillar of FODE experiments to guide future activation tests.\n● Monitor eco-revenue & trial to gns conversion to validate long-term monetization impact post trial.", "", ""], ["", "", ""], ["Global Business Solutio", "ns Group", "12"], ["Results: POSITIVE DIR. POSITIVE\nIMPACT IMPACT", "", "Call Outs: A D G"], ["", "FLAT\nIMPACT", ""]] | V2: Alt TO (slide 7): IOluNtioSn Gs RGOroUuPp 7 | Alt Date (slide 8): 09/15/2025 | Alt TO (slide 8): ##-##-## | Alt TO (slide 9): purchase” or simplified messaging resonates most with mature, embedded QBO users who are already familiar with | Alt TO (slide 10): 31D Signup” and a +69% uplift in “Clicked to 3ID Signup,” indicating that the | Alt TO (slide 11): treatment. | Alt GET (slide 12): to manually send the wrap | Alt TO (slide 12): mers, validating | Date source: CSV – Current Target Launch Date | Name source: CSV | Business Impact updated from Results Report | Status enriched from Results Report | W2: 6–12 | X2: Copy of FY'25_ CRM Analytics Monthly Experiment_Notebook_AC.pdf
A3: ELM-7084 | B3: TAX Redesign Zero State LP | C3: 01-24-2025 | D3: QBO/QBSP Customers who have not signed-up for 2024 tax year | E3: IOluNtioSn Gs RGOroUuPp 13 | F3: communicating benefits on By making them feel secure and Start QBL Tax for 2024 tax season | G3: GET: QBO/QBSP Customers who have not signed-up for 2024 tax year | TO: IOluNtioSn Gs RGOroUuPp 13 | BY: communicating benefits on By making them feel secure and Start QBL Tax for 2024 tax season | H3: If the TOF is redesigned, for each +1.0 increase in the view-to-start rate* will increase QBL Tax Starts By 10,000 * Results - 24-12-16 to 25-01-15 T1 T2 Con. Δ T1 Δ T2 ITC - T1 ITC - T2 Assignments 19,731 20,148 20,113 Total Starts 1,304 1,074 1,283 21 -209 102 A 84 DIWM, Inc 274 359 429 -155 -70 64 84 C DIFM, Inc 75 37 49 26 -12 153 76 DIWM, Un Inc 955 678 805 150 -127 119 84 B Learnings & Implications ● Overall tax starts are at 102 ITC for T1, but the merchandising | I3: & Implications ● Overall tax starts are at 102 ITC for T1, but the merchandising | J3: QBO | K3: IPD; Email; Landing Page | L3: Trending Positive | Results: 5.1 MEASURE: Complete | M3: Positive Biz Impact | 120 ITC-1 | N3: https://docs.google.com/presentation/d/1DZ46Q5JkxjkSYMQpgnr5bjD-PMn4pnpNAlaZNQ2C35E/edit?usp=sharing | O3: GNS/GNA | P3: 120 | Q3: Ecosystem Revenue | S3: Ecosystem Revenue | U3: [["WRAP REPORT", ""], ["ELM -8355\n[TAX] TY24 Zero State\nPage Optimization \\", ""], ["R5", "5KKYsymog/edit\nGLOBAL BGUlSoIbNaEl SBSus SinOeLsUs SToIOluNtioSn Gs RGOroUuPp", "", ""], ["", "", "", "1"], ["", "", "GLOBAL BGUlSoIbNaEl SBSus SinOeLsUs SToIOluNtioSn Gs RGOroUuPp", ""], ["", "", "", ""], ["WRAP REPORT", "", ""], ["ELM -7084\n[TAX] Zero State Page R", "edesign", ""], ["", "Template v5.0 Updated Aug 2024\nGLOBAL BGUlSoIbNaEl SBSus SinOeLsUs SToIOluNtioSn Gs RGOroUuPp", "", ""], ["", "", "", "2"], ["", "", "GLOBAL BGUlSoIbNaEl SBSus SinOeLsUs SToIOluNtioSn Gs RGOroUuPp", ""], ["", "", "", ""], [""], ["QBL TAX - INTRODUCTION"], [""], [""], ["Business type", "", "DIWM Tax", "DIFM Tax", "Deadline"], ["Inc - In scope", "S Corp", "$489.00", "$1,169.00", "March 17"], ["", "Partnership", "$489.00", "$1,169.00", "March 17"], ["Sole prop", "Sole proprietor", "$169.00", "NA", "April 15"], ["inc (out of scope)", "corporation", "NA", "NA", "NA"], ["Global Business Solutio", "ns Group", "233"], [""], ["STRATEGY & APPROACH"], [""], ["CONTROL “Legacy”"], [""], ["TREATMENT A - “Price Compare”"], [""], ["TREATMENT B - “DIWM focus”", "TREATMENT B - “DIWM focus”"], ["", ""], ["", ""], ["", ""], ["Global Business Solutio", "ns Group", "234"], [""], ["STRATEGY & APPROACH"], ["CONTROL “Legacy”"], [""], ["TREATMENT A - “Price Compare”"], [""], ["TREATMENT B - “DIWM focus”", ""], ["", ""], ["Global Business Solutio", "ns Group", "235"], ["EXPERIMENT RESULTS\nQBL Tax Zero State Page\nWe are looking to increase the traffic-to-start (T2S) rate*\nwho come to QBL Tax Zero State Landing Page, by com\nthe QBL Tax LP, by using IPDs/emails to drive LP traffic.\nBusiness Impact: POSITIVE NEGATIVE\nBIZ IMPACT BIZ IMPACT\nRedesigned QBL Tax LP has delivered sig. higher starts for\nInc) customers (120 ITC , + 150) & will deliver +2100 start\nRedesigned QBL Tax LP has delivered negative performanc\ntype customers, we recommend roll back to control group", "", "EXPERIMENT RESULTS", "", "", "", "Redesign\nof QBO customers\nmunicating benefits on", "", "PRODUCTS: QBLive ● DRIVER: Bryan W. ● QB: ELM 7084 ● SOT:", "", "", "", "", "Deck", "● DATES: 24-12-16 to 25-01-15"], ["", "", "QBL Tax Zero Stat", "", "", "", "Redesign\nof QBO customers\nmunicating benefits on", "", "", "", "", "", "", "", ""], ["", "", "", "", "", "", "", "", "", "", "", "", "", "", ""], ["", "", "", "", "", "", "", "", "", "", "", "", "", "", ""], ["", "", "", "", "", "", "", "", "", "", "", "", "", "", ""], ["", "", "", "", "", "", "", "", "", "", "", "", "", "", ""], ["", "", "", "", "", "", "", "", "", "Learnings & Implications\n● Overall tax starts are at 102 ITC for T1, but the merchandising\nA\nperformance is mixed\nB ● DIWM Un Inc customers account for ~70% of starts, T1 has shown a\n120 ITC.\nC● The goodness observed in DIFM - Inc group for T1 isn't enough to\ncompensate for the drop in DIWM - Inc gGrloobuapl B ucsuinsestso Smoluetirosn.s Group 236", "", "", "", "", ""], ["", "Business Impact: POSITIVE NEGATIVE\nBIZ IMPACT BIZ IMPACT\nRedesigned QBL Tax LP has delivered sig. higher starts for\nInc) customers (120 ITC , + 150) & will deliver +2100 start\nRedesigned QBL Tax LP has delivered negative performanc\ntype customers, we recommend roll back to control group", "", "", "", "", "Sole prop (DIWM Un\ns by end of peak season.\ne across other biz entity", "", "", "", "", "", "", "", ""], ["", "", "", "", "", "", "", "Un\nason.\nentity", "", "", "", "", "", "", ""], ["", "", "", "", "", "", "Sole prop (DIWM", "Un", "", "", "", "", "", "", ""], ["", "", "", "", "", "", "s by end of peak se\ne across other biz", "", "", "", "", "", "", "", ""], ["", "", "", "", "", "", "design.", "", "", "", "", "", "", "", ""], ["", "", "", "", "", "", "", "", "", "", "", "", "", "", ""], ["", "", "", "", "", "Call Outs: A D G", "", "", "", "", "", "", "", "", ""], ["", "", "", "FLAT &\nROLL OUT", "", "", "", "", "", "", "", "", "", "", ""], ["", "", "", "", "", "", "", "", "", "", "", "", "Use this google\ntemplate for KPIs", "", ""], ["", "", "", "", "", "", "", "", "", "", "", "", "", "", ""], [""], [""], ["", "T1", "T2", "Con.", "Δ T1", "Δ T2", "ITC - T1", "ITC - T2"], ["Assignments", "19,731", "20,148", "20,113", "", "", "", ""], ["Total Starts", "1,304", "1,074", "1,283", "21", "-209", "102 A", "84"], ["DIWM, Inc", "274", "359", "429", "-155", "-70", "64", "84"], ["DIFM, Inc", "75", "37", "49", "26", "-12", "C\n153", "76"], ["DIWM, Un Inc", "955", "678", "805", "150", "-127", "119", "84 B"], ["M - Inc gGrloobuapl B ucsuinsestso Smoluetiro", "sn.s Group", "236"], ["Use this google"], ["emplate for KPIs"]] | V3: Campaign re-appears on slide 232 (gap from slide 13) | Alt TO (slide 232): IOluNtioSn Gs RGOroUuPp 232 | Alt TO (slide 233): mers - ~1Mn traffic for TY 23 - 25k Starts for TY 23 | Alt TO (slide 235): rship | Alt Date (slide 236): 24-12-16 | Alt TO (slide 236): 25-01-15 | Date source: CSV – Current Target Launch Date | Name source: CSV | Business Impact updated from Results Report | Status enriched from Results Report | W3: 13–236 | X3: Copy of FY'25_ CRM Analytics Monthly Experiment_Notebook_AC.pdf
A4: ELM-8355 | B4: [TAX] TY24 Zero State Page Optimization Test | C4: 08-27-2025 | D4: Existing QBO/SP customers Sole Prop, Partnership, S-Corp | E4: 25-09-15 | F4: By making QBO customers confident that filing taxes directly in | G4: GET: Existing QBO/SP customers Sole Prop, Partnership, S-Corp | TO: 25-09-15 | BY: By making QBO customers confident that filing taxes directly in | H4: If the TOF is redesigned, for each +1.0 increase in the view-to-start rate will increase QBL Tax Starts By 5,000 Results Treatment Control Δ ITC Assignments 10,827 10,827 Total Starts 577 528 49 109 A Learnings & Implications ● Overall tax starts are at 109 ITC for Treatment, but the merchandising A performance is mixed | I4: & Implications ● Overall tax starts are at 109 ITC for Treatment, but the merchandising A performance is mixed & Implications ● Overall tax starts are at 223 ITC with 149 Incr starts for Treatment, A this is in line with unknown entity type starts | J4: QBO | K4: Landing Page | L4: Trending Positive | Results: 5.1 MEASURE: Complete | M4: Positive Biz Impact | 109 ITC-1 | 223 ITC-2 | N4: https://docs.google.com/presentation/d/1NRL_Alxvw2IabKQdV0SCRADbZZk1GYQYaKGGNy4pLV0/edit?usp=sharing | O4: Retention Rate | P4: 109 | Q4: Retention Rate | R4: 223 | U4: [["EXPERIMENT RESULTS\nQBL Tax Zero State Page\nIncrease the traffic-to-start (T2S) rate among QBO custo\nTax Zero State Landing Page by clearly communicating\nthrough targeted cobranding with TurboTax for Sole Pro\nS Corps and Partnerships\nBusiness Impact: POSITIVE\nBIZ IMPACT\nRedesigned QBL Tax LP with TT Co branding has delivered\nprop (DIWM Un Inc) customers (109 ITC , + 49) & will deli\nof peak season TY 25.", "", "EXPERIMENT RESULTS", "", "Redesign\nmers visiting the QBL\nproduct benefits\nprietors & DIWM for", "", "PRODUCTS: QBLive ● DRIVER: Bryan W. ● QB: ELM 8355 ● SOT: Deck ● DATES: 25-08-16 to 25-09-15\nObjective\nGet Existing QBO/SP customers Sole Prop, Partnership, S-Corp\nTo Sign up for QBL Tax\nBy By making QBO customers confident that filing taxes directly in\nQBO by showing them the tax preparation credentials of TurboTax\nHypothesis\nIf the TOF is redesigned, for each +1.0 increase in the view-to-start rate\nwill increase QBL Tax Starts By 5,000\nResults\nTreatment Control Δ ITC\nAssignments 10,827 10,827\nTotal Starts 577 528 49 109\nA\nLearnings & Implications\n● Overall tax starts are at 109 ITC for Treatment, but the merchandising\nA\nperformance is mixed\n14\nGlobal Business Solutions Group", "", ""], ["", "", "QBL Tax Zero Stat", "", "Redesign\nmers visiting the QBL\nproduct benefits\nprietors & DIWM for", "", "", "", ""], ["", "", "", "", "", "", "", "", ""], ["", "", "", "", "", "", "", "Learnings & Implications\n● Overall tax starts are at 109 ITC for Treatment, but the merchandising\nA\nperformance is mixed", ""], ["", "", "", "", "", "", "performance is mixed", "performance is mixed", ""], ["", "Business Impact: POSITIVE\nBIZ IMPACT\nRedesigned QBL Tax LP with TT Co branding has delivered\nprop (DIWM Un Inc) customers (109 ITC , + 49) & will deli\nof peak season TY 25.", "", "", "sig. higher starts fo\nver +2000 starts b", "r Sole\ny end", "", "", ""], ["", "", "", "", "", "", "", "", ""], ["", "", "", "", "", "", "", "", "14"], ["Deck", "● DATES: 25-08-16 to 25-09-15"], ["", "Treatment", "Control", "Δ", "ITC"], ["Assignments", "10,827", "10,827", "", ""], ["Total Starts", "577", "528", "49", "109\nA"], ["", "Call Outs: A D G"], ["FLAT &\nROLL OUT", ""], ["", ""], ["Use this google"], ["emplate for KPIs"], ["EXPERIMENT RESULTS\nQBL Tax Zero State Page\nIncrease the traffic-to-start (T2S) rate among QBO custo\nTax Zero State Landing Page by clearly communicating\nthrough showing only DIWM for S Corps and Partnershi\nBusiness Impact: POSITIVE\nBIZ IMPACT\nRedesigned QBL Tax LP with TT Co branding has delivered\nprop (DIWM Un Inc) customers (223 ITC , + 149) & will de\nof peak season TY 25.", "", "EXPERIMENT RESULTS", "", "", "Redesign\nmers visiting the QBL\nproduct benefits\nps", "", "PRODUCTS: QBLive ● DRIVER: Bryan W. ● QB: ELM 8355 ● SOT: Deck ● DATES: 25-08-16 to 25-09-15\nObjective\nGet Existing QBO/SP customers Sole Prop, Partnership, S-Corp\nTo Sign up for QBL Tax\nBy By making QBO customers confident that filing taxes directly in\nQBO by showing them only DIWM product\nHypothesis\nIf the TOF is redesigned, for each +1.0 increase in the view-to-start rate\nwill increase QBL Tax Starts By 5,000\nResults\nTreatment Control Δ ITC\nAssignments 4,065 4,232\nTotal Starts 270 121 149 223 A\nLearnings & Implications\n● Overall tax starts are at 223 ITC with 149 Incr starts for Treatment,\nA\nthis is in line with unknown entity type starts\n15\nGlobal Business Solutions Group", "", ""], ["", "", "QBL Tax Zero Stat", "", "", "Redesign\nmers visiting the QBL\nproduct benefits\nps", "", "", "", ""], ["", "", "", "", "", "", "", "", "", ""], ["", "", "", "", "", "", "", "", "Learnings & Implications\n● Overall tax starts are at 223 ITC with 149 Incr starts for Treatment,\nA\nthis is in line with unknown entity type starts", ""], ["", "", "", "", "", "", "", "this is in line with unknown entity type starts", "this is in line with unknown entity type starts", ""], ["", "Business Impact: POSITIVE\nBIZ IMPACT\nRedesigned QBL Tax LP with TT Co branding has delivered\nprop (DIWM Un Inc) customers (223 ITC , + 149) & will de\nof peak season TY 25.", "", "", "", "sig. higher starts fo\nliver +4000 starts", "r Sole\nby end", "", "", ""], ["", "", "", "", "", "", "", "", "", ""], ["", "", "", "", "", "", "", "", "", "15"], ["Deck", "● DATES: 25-08-16 to 25-09-15"], ["", "Treatment", "Control", "Δ", "ITC"], ["Assignments", "4,065", "4,232", "", ""], ["Total Starts", "270", "121", "149", "223 A"], ["", "Call Outs: A D G"], ["FLAT &\nROLL OUT", ""], ["", ""]] | V4: Alt Hypothesis (slide 15): If the TOF is redesigned, for each +1.0 increase in the view-to-start rate will increase QBL Tax Starts By 5,000 Results Treatment Control Δ ITC Assignments 4,065 4,232 Total Starts 270 121 149 223 A Learnings & Implications ● Overall tax starts are at 223 ITC with 149 Incr starts for Treatment, A this is in line with unknown entity type starts | Date source: CSV – Current Target Launch Date | Name source: CSV | Business Impact updated from Results Report | Status enriched from Results Report | W4: 14–15 | X4: Copy of FY'25_ CRM Analytics Monthly Experiment_Notebook_AC.pdf
A5: ELM-8764 | B5: TCO Learning Plan: Test 2: SKU Price Increase and Upgrade to Suite giving Customers Choice Dry Test | C5: 09-30-2025 | D5: her capabilities | E5: IOluNtioSn Gs RGOroUuPp 16 | G5: GET: her capabilities | TO: IOluNtioSn Gs RGOroUuPp 16 | H5: Dry Test: Existing Customers SKU Price Increase > Upgrade to Suite giving Customers Choice | I5: Plan: Test 2: SKU > Suite Migration giving Customers Choice & Current H/L & No Change Pricing Options Dry Test SWAG Effort Size When given the option, customers ●A High intention to “Downgrade to Suite” was a result of features offered on a Suite showed a best value for adopt Suites through downgrades | J5: Bill Pay | K5: IPD; Landing Page | L5: Positive | U5: [["WRAP REPORT", "", ""], ["TCO Dry Tests\n● ELM-8764 (Dry Test 2)\n● ELM-8929 (Dry Test 4)\n● ELM-8777 (Dry Test 3)", "", ""], ["", "Template v6.0 Updated Sept 2025\nGLOBAL BGUlSoIbNaEl SBSus SinOeLsUs SToIOluNtioSn Gs RGOroUuPp", "", ""], ["", "", "", "1"], ["", "", "GLOBAL BGUlSoIbNaEl SBSus SinOeLsUs SToIOluNtioSn Gs RGOroUuPp", ""], ["", "", "", ""], ["Global Business Solutio", "ns Group", "17"], ["TCO Dry Test Customer Experience"], [""], ["What’s a dry test?\nA dry test is a method used to gauge the potential success of a product or campaign before fully launching it.\nIt involves creating a simulated version of the product or campaign and presenting it to a select group of consumers to\ngather their feedback and measure their interest.\nCustomer Experience\nThank You Modal\nNon-Dismissible IPD - Dry Test LP Survey /Form Gift card\nPop up of modal with\nBottom Drawer each CTA", ""], ["", ""], ["", "Customer will\nbe emailed a\nGift card for\nparticipation"], ["Thank You Modal\nPop up of modal with\neach CTA"], [""], [""], [""], [""], [""], ["Global Business Solut", "ions Group", "18"], ["SOURCE OF TRUTH\nELM - 8764\nTCO Learning Plan: Test 2: SKU > Suite\nMigration giving Customers Choice &\nCurrent H/L & No Change Pricing Options\nDry Test\nELM Driver: Dan Eliab\nCRM Analytics: Andre Remy\nELM Workstream: SMB\nDate: 09-11-25\nELM Quickbase Record: ELM-8764\nWorkbook: Link\nBusiness Brief: N/A\nSlack Channel: Link", "SWAG Effort Size\nMega\nGlobal Business Solutions Group\nTemplate v6.0 Updated Jan.. 2025", ""], ["SOURCE OF TRUTH", ""], ["", ""], ["ELM - 8764\nTCO Learning Plan: Test 2: SKU > Suite\nMigration giving Customers Choice &\nCurrent H/L & No Change Pricing Options\nDry Test", ""], ["Mega"], [""], ["", "", "", "", ""], ["Context\nDry Test 2 Price Structure\nCurrent Pricing\nSKU Current SKU Price\nSS $38\nESS $75\nPL $115\nADV $275\nCurrent SKU Price + Suite Price = SKU Price + $10\nSKU New SKU Price Suite Price\nESS $75 $85\nPL $115 $125\nADV $275 $285\nLow Price Increase in SKU (except SS) + Low Suite Price\nSKU New SKU Price Suite Price\nSS $38 $40\nESS $80 $85\nPL $135 $140\nADV $295 $305\nHigh Price Increase in SKU (except SS) + High Suite Price\nSKU New SKU Price Suite Price\nSS $38 $45\nESS $85 $95\nPL $140 $155\nADV $315 $340\nCreatives: [Link to Figma]", "", "", "", ""], ["", "", "", "Creative for PLUS: Current SKU Price + Suite Price = SKU Price + $10", ""], ["", "Context\nDry Test 2 Price Structure", "Context", "", ""], ["", "", "", "", ""], ["Current Pricing", ""], ["SKU", "Current SKU Price"], ["SS", "$38"], ["ESS", "$75"], ["PL", "$115"], ["ADV", "$275"], ["Current SKU Price + Suite Price = SKU Price + $10", "", ""], ["SKU", "New SKU Price", "Suite Price"], ["ESS", "$75", "$85"], ["PL", "$115", "$125"], ["ADV", "$275", "$285"], ["Low Price Increase in SKU (except SS) + Low Suite Price", "", ""], ["SKU", "New SKU Price", "Suite Price"], ["SS", "$38", "$40"], ["ESS", "$80", "$85"], ["PL", "$135", "$140"], ["ADV", "$295", "$305"], ["High Price Increase in SKU (except SS) + High Suite Price", "", ""], ["SKU", "New SKU Price", "Suite Price"], ["SS", "$38", "$45"], ["ESS", "$85", "$95"], ["PL", "$140", "$155"], ["ADV", "$315", "$340"], ["", "IntGuliot Cbaoln Bfiudseinnetisasl aSnodlu Ptiro", "onpsr iGertaoruyp", "20"], ["", "", "Call Outs: A D G"], ["", "FLAT\nIMPACT", ""], ["STILL BAKING", "", ""], ["Dry Test 02 Results\nWhen given the option, customers\nadopt Suites through downgrades\nTreatment 1 - SKU at Current Price | Suite Price at an additional $10 with downgrade option\nSKU Keep SKU * Downgrade to Suite Switch to Suite Cancel Revenue Impact\nSS N/A N/A N/A N/A N/A\nESS 83.2% 16.8% 0.0% 0.0% -$68.1 M\nPL 87.9% 10.5% 1.3% 0.3% -$49.9 M\nADV 88.4% 9.4% 2.2% 0.0% -$50.1 M\nTOTAL 86.5% 12.3% A 1.1% 0.1% -$168.1 M\nTreatment 2 - SKUs (except SS) at New Low price | Suite at New Low price with downgrade option\nSKU Keep SKU * Downgrade to Suite Switch to Suite Cancel Revenue Impact\nSS 94% N/A 5% 1% -$3.7 M\nESS 83.6% 14.2% 1.6% 0.6% -$16.6 M\nPL 83.2% 15.2% 1.4% 0.3% $181.4 M D\nADV 85.0% 12.0% 2.2% 0.7% -$2.0 M\nTOTAL 86.4% 10.5% 2.5% 0.6% $159.1 M\nTreatment 3 - SKUs (except SS) at New Hish price | Suite at New High price with downgrade option\nSKU Keep SKU * Downgrade to Suite Switch to Suite Cancel Revenue Impact\nSS 98% 0% 2% 0% $4.1 M\nESS 83% 16% 1% 1% $44.0 M\nPL 85% 16% 1% 0% $270.6 M\nADV 85% 13% 1% 1% $62.3 M\nTOTAL 87.0% 11.2% 1.5% 0.4% $380.9 M\n* Assumes that the 43% of customers that didn’t answer will remain in their current SKU", "", "", "", "", "", "", "", "Insights\n●A High intention to “Downgrade to Suite” was a result of\nfeatures offered on a Suite showed a best value for\nmoney:\n○ Creatives didn’t show features trade-off at\ndowngrade\n○ For a lower price, downgrades to a Suite gave\ncustomers more free ACH and included Payroll\n●B Downgrades are the main driver for Revenue loss\nwhile the Price increase is driving the goodness in\nRevenue\n●C ~90% of Suite adoption would happen through\nDowngrades\n●D The price structure of PLUS allows this SKU to yield a\npositive revenue (see next slide)\n-13%\n-43%\nGlobal Business Solutions Group 21", ""], ["", "Dry Test 02 Results\nWhen given the option, customers\nadopt Suites through downgrades", "Dry Test 02 Results", "", "", "", "", "", "", ""], ["", "Treatment 1 - SKU at Current Price | Suite Price at an additional $10 with downgrade option", "", "", "", "", "", "", "", ""], ["", "SKU", "", "Keep SKU *", "Downgrade to Suite", "Switch to Suite", "Cancel", "Revenue Impact", "", ""], ["", "SS", "", "N/A", "N/A", "N/A", "N/A", "N/A", "", ""], ["", "ESS", "", "83.2%", "16.8%", "0.0%", "0.0%", "-$68.1 M", "", ""], ["", "PL", "", "87.9%", "10.5%", "1.3%", "0.3%", "-$49.9 M", "", ""], ["", "ADV", "", "88.4%", "9.4%", "2.2%", "0.0%", "-$50.1 M", "", ""], ["", "TOTAL", "", "86.5%", "12.3% A", "1.1%", "0.1%", "-$168.1 M", "", ""], ["Treatment 2 - SKUs (except SS) at New Low price | Suite at New Low price with downgrade option", "", "", "", "", ""], ["SKU", "Keep SKU *", "Downgrade to Suite", "Switch to Suite", "Cancel", "Revenue Impact"], ["SS", "94%", "N/A", "5%", "1%", "-$3.7 M"], ["ESS", "83.6%", "14.2%", "1.6%", "0.6%", "-$16.6 M"], ["PL", "83.2%", "15.2%", "1.4%", "0.3%", "$181.4 M D"], ["ADV", "85.0%", "12.0%", "2.2%", "0.7%", "-$2.0 M"], ["TOTAL", "86.4%", "10.5%", "2.5%", "0.6%", "$159.1 M"], ["Treatment 3 - SKUs (except SS) at New Hish price | Suite at New High price with downgrade option", "", "", "", "", ""], ["SKU", "Keep SKU *", "Downgrade to Suite", "Switch to Suite", "Cancel", "Revenue Impact"], ["SS", "98%", "0%", "2%", "0%", "$4.1 M"], ["ESS", "83%", "16%", "1%", "1%", "$44.0 M"], ["PL", "85%", "16%", "1%", "0%", "$270.6 M"], ["ADV", "85%", "13%", "1%", "1%", "$62.3 M"], ["TOTAL", "87.0%", "11.2%", "1.5%", "0.4%", "$380.9 M"], ["Global Business Solutio", "ns Group", "21"]] | V5: Alt Campaign Name (slide 17): TCO Dry Test 2 - Introduce Suites with options to upgrade/downgrade to a Suite, Keep plan, or | Alt TO (slide 17): mers | Alt TO (slide 18): mer Experience | Alt Date (slide 19): 09-11-25 | Alt TO (slide 19): mers Choice & | Alt TO (slide 20): Figma] | Alt Product (slide 21): Payroll | Alt TO (slide 21): mers | Date source: CSV – Current Target Launch Date | Name source: CSV | Hypothesis filled from CSV Project Description CSV (Inferred for review) | W5: 16–21 | X5: Copy of FY'25_ CRM Analytics Monthly Experiment_Notebook_AC.pdf
A6: ELM-8929 | B6: TCO Learning Plan: Test 4 Upgrade to Suite, New Pricing and NO Downgrade | C6: 10-07-2025 | E6: Suite, New Pricing and NO Downgrade | G6: TO: Suite, New Pricing and NO Downgrade | H6: Fast follow of Dry Test 2 ELM 8764. Test 4 will give customer options to upgrade to Suite with new pricing and NO downgrade option. | I6: Plan: Test 4: Upgrade to Suite, New Pricing and NO Downgrade SWAG Effort Size | K6: IPD; Landing Page | L6: Not found (Inferred for review) | U6: [["SOURCE OF TRUTH\nELM - 8929\nTCO Learning Plan: Test 4: Upgrade to\nSuite, New Pricing and NO Downgrade\nELM Driver: Dan Eliab\nCRM Analytics: Andre Remy\nELM Workstream: SMB\nDate: 10-3-25\nELM Quickbase Record: ELM-8929\nWorkbook: Link (Same workbook was used for ELM-8764 and ELM-8929)\nBusiness Brief: N/A\nSlack Channel: Link (Same slack channel was used for ELM-8764 and ELM-8929)", "SWAG Effort Size\nSmall\nGlobal Business Solutions Group\nTemplate v6.0 Updated Jan.. 2025", ""], ["SOURCE OF TRUTH", ""], ["", ""], ["ELM - 8929\nTCO Learning Plan: Test 4: Upgrade to\nSuite, New Pricing and NO Downgrade", ""], ["Small"], [""]] | V6: Date source: CSV – Current Target Launch Date | Name source: CSV | Hypothesis filled from CSV Project Description CSV (Inferred for review) | W6: 22 | X6: Copy of FY'25_ CRM Analytics Monthly Experiment_Notebook_AC.pdf
A7: ELM-8047 | B7: FY25 MAR GAP CLOSER: TEST 4 - S2: Price in Agents: Existing Customer Dry Test | C7: 04-02-2025 | E7: mers ● Gov’t officials | F7: effort and Stop: Relying on price or discounts alone to drive adoption. | G7: TO: mers ● Gov’t officials | BY: effort and Stop: Relying on price or discounts alone to drive adoption. | H7: Test 3 Price points: 4 SKU lineup - If we add agentic experiences across the lineup and clearly communicate the value, we can minimize the churn/downgrade impact of increased prices with existing customers. Estimated assets needed: landing pages (versioned for different price levels and SKUs) and bottom drawer IPD. May be able to leverage parts of ACQ price line up. https://docs.google.com/spreadsheets/d/1b4XDWwIw_ZW8L_iAkcvrHsESJHbh06ftKentnFD6KZE/edit?gid=0#gid=0&fvid=2130047774 | I7: 18% of Customers would upgrade A● 18% of customers would switch to a Suite when there’s no price increase. That intention drops up to to a Suite 2% when the Suite is offered at a higher price compared to SKU B● The intention to switch to a Suite is higher at higher SKU at Current Price | Suite Price = SKU Price SKUs. Customers in highers SKU could need SKU Keep SKU * Switch to Suite Cancel Revenue Impact additional features to run their businesses. SS 87.8% 12.2% 0.0% $0.0 M ESS 83.2% 16.5% 0.3% -$3.0 M C● ~1% of customers showed an intent to cancel their PL 76.7% 23.1% 0.3% -$4.6 M subscription when there’s a price increase; which is ADV 77.1% 21.7% 1.3% -$12.6 M very close to the observed behavior during July’s TOTAL 81.6% 18.0% A 0.4% -$20.1 M price increase. SKUs at New Low price | Suite at New Low price SKU Keep SKU* Switch to Suite Cancel Revenue Impact SS 94.3% 5.1% 0.6% -$3.7 M ESS 97.4% 1.6% 1.1% $63.5 M B PL 96.8% 2.7% 0.5% $292.2 M ADV 93.5% 4.5% 1.9% $53.0 M TOTAL 95.7% 3.3% 1.0% $405.0 M -15% SKUs at New High price | Suite at New High price SKU Keep SKU * Switch to Suite Cancel Revenue Impact -40% SS 97.8% 2.2% 0.0% $4.1 M ESS 97.2% 2.0% 0.8% $143.3 M PL 96.7% 2.0% 1.3% $353.2 M ADV 96.2% 2.2% 1.6% $128.1 M TOTAL 97.0% 2.1% 0.9% C $628.7 M * Assumes that the 40% of customers that didn’t answer will remain in their current SKU Global Business Solutions Group 24 and implications? LEARNING / INSIGHTS HOW WE KNOW THIS IMPLICATION Equal Price Does Not Equal When AIO Suites are offered at current SKU prices, only 18% Start: Test and learn into consumption strategy that drive active use Appeal (Low Adoption From SKU switched, showing resistance is driven by effort and Stop: Relying on price or discounts alone to drive adoption. to Suite Even at Price Parity). uncertainty, not cost Continue: Use real-customer proof and transition stories to demonstrate ease and Increased price ($5-10) Suite adoption drops to 3.3% when offered at a price benefit. significantly reduced adoption difference of $5-$10 and 2.1% when offered at a price difference of $10-$25 (Source: AIO Dry Test - Test 04) Higher SKU customers are more Customers showed a higher intent to switch to a Suite when Start: Build SKU-specific strategies for Suites by making higher level suites more likely to switch to a Suite. they are on higher SKUs. On average, 10% Adv customers compelling as they have a higher chance of adoption. The ICP’s for plus and MM/higher SKU likely more open switch to a suite compared to 9% in Plus, 7% in Essentials, and advanced will need to be revisited in conjunction with conjoint inputs. to learn about AIO. 7% in Simple Start. (Source: AIO Dry Test - Test 04) Risk of SKU-to-Suite Downgrades Initial dry test showed significant 18-22% downgrade rates Start: Clearly differentiate feature/value prop across SKUs and highlight what and Revenue Impact (varies by SKU and price point) driven by side-by-side customer is going to lose with downgrade path. Restrict organic discovery of SKU placement of downgrade suite options. downgrade paths. If PLUS is removed, most customers A● Even though all projections show a negative revenue impact, Scenario 1 (SKU at Current Price | Suite Price would downgrade hurting revenue at SKU Price + $10) is the one with less negative impact due to the higher adoption of ADV Suite. ○ To breakeven in Scenario 1, ADV Suite Repository Upgrade SWAG Effort Size | J7: Payments | K7: IPD; Landing Page | L7: Negative | U7: [["", "", "", ""], ["Context\nDry Test 4 Design\nCurrent Pricing\nSKU Current SKU Price\nSS $38\nESS $75\nPL $115\nADV $275\nSKU Price = Suite Price (No Price Increase)\nSKU SKU Price Suite Price\nSS $38 $38\nESS $75 $75\nPL $115 $115\nADV $275 $275\nLow Price Increase in SKU | Low Suite Price\nSKU New SKU Price Suite Price\nESS $80 $85\nPL $135 $140\nADV $295 $305\nHigh Price Increase in SKU | High Suite Price\nSKU New SKU Price Suite Price\nESS $85 $95\nPL $140 $155\nADV $315 $340\nCreatives: [Link to Slide Deck]", "", "", "Creative for PLUS: SKU Price = Suite Price (No Price Increase)\nAUDIENCE EXCLUSIONS\n● QBO Simple Start customers ● Gov’t officials\n● Monthly subscribers ● Trialers\n● Paid ● Customers with attached products (Payroll, Payments, BillPay,\n● Tenure: Greater than 6 months since signup Live, Mailchimp)\n● Master Admin ● Accountant attached\n● Wholesale\n● Customers on a discount\n● IES\n● Part of FY’25 Agents Dry Tests: ELM-8047,ELM-8048,ELM-8077\n● Anyone part of TCO Dry Test 2 (ELM-8764) and Dry Test 3\n(ELM-8477)\n● For PLUS ONLY: Customers that used inventory and projects\nmanagement features\nGlobal Business Solutions Group 23"], ["", "Context\nDry Test 4 Design", "Context", ""], ["Creative for PLUS: SKU Price = Suite Price (No Price Increase)"], [""], ["Current Pricing", ""], ["SKU", "Current SKU Price"], ["SS", "$38"], ["ESS", "$75"], ["PL", "$115"], ["ADV", "$275"], ["SKU Price = Suite Price (No Price Increase)", "", ""], ["SKU", "SKU Price", "Suite Price"], ["SS", "$38", "$38"], ["ESS", "$75", "$75"], ["PL", "$115", "$115"], ["ADV", "$275", "$275"], ["Low Price Increase in SKU | Low Suite Price", "", ""], ["SKU", "New SKU Price", "Suite Price"], ["ESS", "$80", "$85"], ["PL", "$135", "$140"], ["ADV", "$295", "$305"], ["High Price Increase in SKU | High Suite Price", "", ""], ["SKU", "New SKU Price", "Suite Price"], ["ESS", "$85", "$95"], ["PL", "$140", "$155"], ["ADV", "$315", "$340"], ["Global Business Solutio", "ns Group", "23"], ["Dry Test 04 Results\n18% of Customers would upgrade\nto a Suite\nSKU at Current Price | Suite Price = SKU Price\nSKU Keep SKU * Switch to Suite Cancel Revenue Impact\nSS 87.8% 12.2% 0.0% $0.0 M\nESS 83.2% 16.5% 0.3% -$3.0 M\nPL 76.7% 23.1% 0.3% -$4.6 M\nADV 77.1% 21.7% 1.3% -$12.6 M\nTOTAL 81.6% 18.0% A 0.4% -$20.1 M\nSKUs at New Low price | Suite at New Low price\nSKU Keep SKU* Switch to Suite Cancel Revenue Impact\nSS 94.3% 5.1% 0.6% -$3.7 M\nESS 97.4% 1.6% 1.1% $63.5 M\nB\nPL 96.8% 2.7% 0.5% $292.2 M\nADV 93.5% 4.5% 1.9% $53.0 M\nTOTAL 95.7% 3.3% 1.0% $405.0 M\nSKUs at New High price | Suite at New High price\nSKU Keep SKU * Switch to Suite Cancel Revenue Impact\nSS 97.8% 2.2% 0.0% $4.1 M\nESS 97.2% 2.0% 0.8% $143.3 M\nPL 96.7% 2.0% 1.3% $353.2 M\nADV 96.2% 2.2% 1.6% $128.1 M\nTOTAL 97.0% 2.1% 0.9% C $628.7 M\n* Assumes that the 40% of customers that didn’t answer will remain in their current SKU", "", "", "Insights\nA● 18% of customers would switch to a Suite when\nthere’s no price increase. That intention drops up to\n2% when the Suite is offered at a higher price\ncompared to SKU\nB● The intention to switch to a Suite is higher at higher\nSKUs. Customers in highers SKU could need\nadditional features to run their businesses.\nC● ~1% of customers showed an intent to cancel their\nsubscription when there’s a price increase; which is\nvery close to the observed behavior during July’s\nprice increase.\n-15%\n-40%\nGlobal Business Solutions Group 24", ""], ["", "Dry Test 04 Results\n18% of Customers would upgrade\nto a Suite", "Dry Test 04 Results", "", ""], ["SKU at Current Price | Suite Price = SKU Price", "", "", "", "", "", ""], ["SKU", "Keep SKU *", "Switch to Suite", "", "", "Cancel", "Revenue Impact"], ["SS", "87.8%", "12.2%", "", "", "0.0%", "$0.0 M"], ["ESS", "83.2%", "16.5%", "", "", "0.3%", "-$3.0 M"], ["PL", "76.7%", "23.1%", "", "", "0.3%", "-$4.6 M"], ["ADV", "77.1%", "21.7%", "", "", "1.3%", "-$12.6 M"], ["TOTAL", "81.6%", "", "18.0% A", "", "0.4%", "-$20.1 M"], ["SKUs at New Low price | Suite at New Low price", "", "", "", "", "", ""], ["SKU", "Keep SKU*", "Switch to Suite", "", "", "Cancel", "Revenue Impact"], ["SS", "94.3%", "", "5.1%", "", "0.6%", "-$3.7 M"], ["ESS", "97.4%", "", "1.6%", "", "1.1%", "$63.5 M"], ["PL", "96.8%", "", "2.7%", "B", "0.5%", "$292.2 M"], ["ADV", "93.5%", "", "4.5%", "", "1.9%", "$53.0 M"], ["TOTAL", "95.7%", "3.3%", "", "", "1.0%", "$405.0 M"], ["SKUs at New High price | Suite at New High price", "", "", "", "", "", ""], ["SKU", "Keep SKU *", "Switch to Suite", "Cancel", "", "", "Revenue Impact"], ["SS", "97.8%", "2.2%", "0.0%", "", "", "$4.1 M"], ["ESS", "97.2%", "2.0%", "0.8%", "", "", "$143.3 M"], ["PL", "96.7%", "2.0%", "1.3%", "", "", "$353.2 M"], ["ADV", "96.2%", "2.2%", "1.6%", "", "", "$128.1 M"], ["TOTAL", "97.0%", "2.1%", "", "0.9%", "C", "$628.7 M"], ["Global Business Solutio", "ns Group", "24"], ["LEARNING / INSIGHTS", "HOW WE KNOW THIS", "IMPLICATION"], ["Equal Price Does Not Equal\nAppeal (Low Adoption From SKU\nto Suite Even at Price Parity).\nIncreased price ($5-10)\nsignificantly reduced adoption", "When AIO Suites are offered at current SKU prices, only 18%\nswitched, showing resistance is driven by effort and\nuncertainty, not cost\nSuite adoption drops to 3.3% when offered at a price\ndifference of $5-$10 and 2.1% when offered at a price\ndifference of $10-$25\n(Source: AIO Dry Test - Test 04)", "Start: Test and learn into consumption strategy that drive active use\nStop: Relying on price or discounts alone to drive adoption.\nContinue: Use real-customer proof and transition stories to demonstrate ease and\nbenefit."], ["Higher SKU customers are more\nlikely to switch to a Suite.\nMM/higher SKU likely more open\nto learn about AIO.", "Customers showed a higher intent to switch to a Suite when\nthey are on higher SKUs. On average, 10% Adv customers\nswitch to a suite compared to 9% in Plus, 7% in Essentials, and\n7% in Simple Start.\n(Source: AIO Dry Test - Test 04)", "Start: Build SKU-specific strategies for Suites by making higher level suites more\ncompelling as they have a higher chance of adoption. The ICP’s for plus and\nadvanced will need to be revisited in conjunction with conjoint inputs."], ["Risk of SKU-to-Suite Downgrades\nand Revenue Impact", "Initial dry test showed significant 18-22% downgrade rates\n(varies by SKU and price point) driven by side-by-side\nplacement of downgrade suite options.\nSecond dry test does not allow customers to downgrade.\nSimilarly, GA will also not have the downgrade option side by\nside but there is a risk of customers downgrading when they\nfind these options organically. Baseline downgrade rates are\n0.2% | 120 ITPY.\n(Source: AIO Dry Test - Test 02, Downgrade Trends)", "Start: Clearly differentiate feature/value prop across SKUs and highlight what\ncustomer is going to lose with downgrade path. Restrict organic discovery of SKU\ndowngrade paths.\nStop: Giving away lot of valuable features in lower SKU’s. Presenting lower Suites\nalongside higher SKUs without feature trade-offs.\nContinue: Iterate on SKU features and pricing"], ["Global Business Solutio", "ns Group", "25"], ["", "", "Creative for PLUS: SKUs at New High price | Suite at New High price", ""], ["", "", "", ""], ["", "Dry Test 3 Design", "", ""], ["", "", "", ""], ["", "SKU PL ESS Suite ADV Suite ADV SKU\nCurrent Price $115 $275\nScenario 1: SKU at Current\nPrice | Suite Price at SKU $85 $285 $275\nPrice + $10\nScenario 2: SKUs at New\nLow price | Suite at New $85 $305 $295\nLow price\nScenario 3: SKUs at New\nHigh price | Suite at New $95 $340 $315\nHigh price\nAUDIENCE\n● QBO PLUS\n● Monthly subscribers\n● Paid\n● 6 months or greater tenure (since customers are price protected if <6 months)\n● Master Admin\nEXCLUSIONS\n● Gov’t officials\n● Trialers\n● Wholesale\n● Accountant-attached\n● Customers on a discount\n● Customers with attached products (Payroll, Payments, BillPay, Live,\nMailchimp)\n● IES\n● Part of prior dry tests ELM-8047,ELM-8048,ELM-8477\n● Part of the other TCO dry test, ELM-8764", "", ""], ["SKU", "PL", "ESS Suite", "ADV Suite", "ADV SKU"], ["Current Price", "$115", "", "", "$275"], ["Scenario 1: SKU at Current\nPrice | Suite Price at SKU\nPrice + $10", "", "$85", "$285", "$275"], ["Scenario 2: SKUs at New\nLow price | Suite at New\nLow price", "", "$85", "$305", "$295"], ["Scenario 3: SKUs at New\nHigh price | Suite at New\nHigh price", "", "$95", "$340", "$315"], ["Global Business Solutio", "ns Group", "27"], ["Dry Test 03 Results\nIf PLUS is removed, most customers\nwould downgrade hurting revenue\nScenario 1: SKU at Current Price | Suite Price at SKU Price + $10\nSKU Downgrade to ESS Suite Upgrade to ADV Suite Upgrade to ADV SKU Cancel Revenue Impact\nPL 82.4% 10.2% 5.6% 1.9% -$9.7 M\nScenario 2: SKUs at New Low price | Suite at New Low price\nSKU Downgrade to ESS Suite Upgrade to ADV Suite Upgrade to ADV SKU Cancel Revenue Impact\nPL 89.7% 2.6% 4.3% 3.4% -$274.4 M\nScenario 3: SKUs at New High price | Suite at New High price\nSKU Downgrade to ESS Suite Upgrade to ADV Suite Upgrade to ADV SKU Cancel Revenue Impact\nPL 97.3% 0.0% 0.9% 1.8% -$295.9 M\n-5%\n-47%", "", "", "Insights\nA● Even though all projections show a negative revenue\nimpact, Scenario 1 (SKU at Current Price | Suite Price\nat SKU Price + $10) is the one with less negative\nimpact due to the higher adoption of ADV Suite.\n○ To breakeven in Scenario 1, ADV Suite\nadoption has to be at least 10.5%\n●B Similar to what was observed in Dry Test 2 and Dry\nTest 4, a high prices are likely to be a barrier to Suite\nadoption (potentially high price sensitivity)\nGlobal Business Solutions Group 28", ""], ["", "Dry Test 03 Results\nIf PLUS is removed, most customers\nwould downgrade hurting revenue", "Dry Test 03 Results", "", ""], ["Scenario 1: SKU at Current Price | Suite Price at SKU Price + $10", "", "", "", "", ""], ["SKU", "Downgrade to ESS Suite", "Upgrade to ADV Suite", "Upgrade to ADV SKU", "Cancel", "Revenue Impact"], ["PL", "82.4%", "10.2%", "5.6%", "1.9%", "-$9.7 M"], ["Scenario 2: SKUs at New Low price | Suite at New Low price", "", "", "", "", ""], ["SKU", "Downgrade to ESS Suite", "Upgrade to ADV Suite", "Upgrade to ADV SKU", "Cancel", "Revenue Impact"], ["PL", "89.7%", "2.6%", "4.3%", "3.4%", "-$274.4 M"], ["Scenario 3: SKUs at New High price | Suite at New High price", "", "", "", "", ""], ["SKU", "Downgrade to ESS Suite", "Upgrade to ADV Suite", "Upgrade to ADV SKU", "Cancel", "Revenue Impact"], ["PL", "97.3%", "0.0%", "0.9%", "1.8%", "-$295.9 M"], ["Global Business Solutio", "ns Group", "28"], ["", "", "", ""], ["WRAP REPORT\nELM - 6651\nPayroll Insights Repository\nUpgrade\nELM Driver: Jamie Peng\nCRM Analytics: Manasa Shankar, Sowmya Lingamneni\nELM Workstream: Attach & Upsell\nDate: ##-##-####\nEPLMr Qeuisckebasne Rteecorrd: ENLM-a665m1 e\nWorkbook: Link\nSlack Channel: Link", "", "", "SWAG Effort Size\nM"], ["", "", "", "29\nTemplate v5.0 Updated Aug 2024"], ["WRAP REPORT"], ["ELM - 6651\nPayroll Insights Repository"], ["ELM Driver: Jamie Peng\nCRM Analytics: Manasa Shankar, Sowmya Lingamneni", ""], ["ELM Workstream: Attach & Upsell\nDate: ##-##-####\nEPLMr Qeuisckebasne Rteecorrd: ENLM-a665m1 e\nWorkbook: Link", ""], ["Slack Channel: Link", ""], ["en\nLink", ""], ["", "Link"], [""], ["29\nv5.0 Updated Aug 20"]] | V7: Alt TO (slide 24): mers would upgrade | Alt TO (slide 25): consumption strategy that drive active use | Campaign re-appears on slide 27 (gap from slide 25) | Alt Campaign Name (slide 27): ,ELM-8048,ELM-8477 | Alt TO (slide 27): mers are price protected if <6 months) | Alt Product (slide 29): Payroll | Alt TO (slide 29): ry | Date source: CSV – Current Target Launch Date | Name source: CSV | Hypothesis filled from CSV Project Description CSV (Inferred for review) | W7: 23–29 | X7: Copy of FY'25_ CRM Analytics Monthly Experiment_Notebook_AC.pdf
A8: ELM-8477 | B8: TCO Learning Plan: Test 3 Existing Customers Remove Plus Dry Test | C8: 10-02-2025 | E8: mers Remove Plus Dry Test | G8: TO: mers Remove Plus Dry Test | H8: Dry Test for existing Plus customers - options of downgrade to ESS Suite or upgrade if Plus SKU is not an option at different prices | I8: Plan: Test 3 Existing Customers Remove Plus Dry Test SWAG Effort Size | K8: IPD; Landing Page | L8: Not found (Inferred for review) | U8: [["SOURCE OF TRUTH\nELM - 8477\nTCO Learning Plan: Test 3 Existing\nCustomers Remove Plus Dry Test\nELM Driver: Dan Eliab\nCRM Analytics: Andre Remy\nELM Workstream: SMB\nDate: 09-11-25\nELM Quickbase Record: ELM-8477\nWorkbook: Link\nBusiness Brief: N/A\nSlack Channel: Link", "SWAG Effort Size\nM\nGlobal Business Solutions Group\nTemplate v6.0 Updated Jan.. 2025", ""], ["SOURCE OF TRUTH", ""], ["SOURCE OF TRUTH", ""], ["ELM - 8477\nTCO Learning Plan: Test 3 Existing\nCustomers Remove Plus Dry Test", ""], ["SWAG Effort Size"], ["M"]] | V8: Date source: CSV – Current Target Launch Date | Name source: CSV | Hypothesis filled from CSV Project Description CSV (Inferred for review) | W8: 26 | X8: Copy of FY'25_ CRM Analytics Monthly Experiment_Notebook_AC.pdf
